[2022-07-22 21:15:38,167] {taskinstance.py:1179} INFO - Dependencies all met for <TaskInstance: my_dag.get_matrix scheduled__2022-07-22T00:00:00+00:00 [queued]>
[2022-07-22 21:15:38,171] {taskinstance.py:1179} INFO - Dependencies all met for <TaskInstance: my_dag.get_matrix scheduled__2022-07-22T00:00:00+00:00 [queued]>
[2022-07-22 21:15:38,171] {taskinstance.py:1376} INFO - 
--------------------------------------------------------------------------------
[2022-07-22 21:15:38,171] {taskinstance.py:1377} INFO - Starting attempt 1 of 1
[2022-07-22 21:15:38,171] {taskinstance.py:1378} INFO - 
--------------------------------------------------------------------------------
[2022-07-22 21:15:38,185] {taskinstance.py:1397} INFO - Executing <Task(PythonOperator): get_matrix> on 2022-07-22 00:00:00+00:00
[2022-07-22 21:15:38,190] {standard_task_runner.py:52} INFO - Started process 6977 to run task
[2022-07-22 21:15:38,192] {standard_task_runner.py:79} INFO - Running: ['airflow', 'tasks', 'run', 'my_dag', 'get_matrix', 'scheduled__2022-07-22T00:00:00+00:00', '--job-id', '8', '--raw', '--subdir', 'DAGS_FOLDER/mydag.py', '--cfg-path', '/tmp/tmpsa3usa9x', '--error-file', '/tmp/tmpxpof7ljd']
[2022-07-22 21:15:38,193] {standard_task_runner.py:80} INFO - Job 8: Subtask get_matrix
[2022-07-22 21:15:38,231] {task_command.py:371} INFO - Running <TaskInstance: my_dag.get_matrix scheduled__2022-07-22T00:00:00+00:00 [running]> on host DESKTOP-5GAFI6N.localdomain
[2022-07-22 21:15:38,275] {taskinstance.py:1589} INFO - Exporting the following env vars:
AIRFLOW_CTX_DAG_OWNER=airflow
AIRFLOW_CTX_DAG_ID=my_dag
AIRFLOW_CTX_TASK_ID=get_matrix
AIRFLOW_CTX_EXECUTION_DATE=2022-07-22T00:00:00+00:00
AIRFLOW_CTX_TRY_NUMBER=1
AIRFLOW_CTX_DAG_RUN_ID=scheduled__2022-07-22T00:00:00+00:00
[2022-07-22 21:15:38,277] {taskinstance.py:1909} ERROR - Task failed with exception
Traceback (most recent call last):
  File "/home/lemon/main/airflow/venv/lib/python3.8/site-packages/airflow/operators/python.py", line 171, in execute
    return_value = self.execute_callable()
  File "/home/lemon/main/airflow/venv/lib/python3.8/site-packages/airflow/operators/python.py", line 189, in execute_callable
    return self.python_callable(*self.op_args, **self.op_kwargs)
  File "/home/lemon/airflow/dags/mydag.py", line 23, in confusion_matrix
    model = load_model("./trained_model.h5")
  File "/home/lemon/main/airflow/venv/lib/python3.8/site-packages/keras/utils/traceback_utils.py", line 67, in error_handler
    raise e.with_traceback(filtered_tb) from None
  File "/home/lemon/main/airflow/venv/lib/python3.8/site-packages/keras/saving/save.py", line 206, in load_model
    raise IOError(f'No file or directory found at {filepath_str}')
OSError: No file or directory found at ./trained_model.h5
[2022-07-22 21:15:38,280] {taskinstance.py:1415} INFO - Marking task as FAILED. dag_id=my_dag, task_id=get_matrix, execution_date=20220722T000000, start_date=20220723T011538, end_date=20220723T011538
[2022-07-22 21:15:38,290] {standard_task_runner.py:92} ERROR - Failed to execute job 8 for task get_matrix (No file or directory found at ./trained_model.h5; 6977)
[2022-07-22 21:15:38,324] {local_task_job.py:156} INFO - Task exited with return code 1
[2022-07-22 21:15:38,340] {local_task_job.py:273} INFO - 0 downstream tasks scheduled from follow-on schedule check
