[2022-07-22 21:22:17,381] {taskinstance.py:1179} INFO - Dependencies all met for <TaskInstance: my_dag.get_matrix manual__2022-07-23T01:22:13.378970+00:00 [queued]>
[2022-07-22 21:22:17,384] {taskinstance.py:1179} INFO - Dependencies all met for <TaskInstance: my_dag.get_matrix manual__2022-07-23T01:22:13.378970+00:00 [queued]>
[2022-07-22 21:22:17,384] {taskinstance.py:1376} INFO - 
--------------------------------------------------------------------------------
[2022-07-22 21:22:17,385] {taskinstance.py:1377} INFO - Starting attempt 1 of 1
[2022-07-22 21:22:17,385] {taskinstance.py:1378} INFO - 
--------------------------------------------------------------------------------
[2022-07-22 21:22:17,395] {taskinstance.py:1397} INFO - Executing <Task(PythonOperator): get_matrix> on 2022-07-23 01:22:13.378970+00:00
[2022-07-22 21:22:17,398] {standard_task_runner.py:52} INFO - Started process 14925 to run task
[2022-07-22 21:22:17,400] {standard_task_runner.py:79} INFO - Running: ['airflow', 'tasks', 'run', 'my_dag', 'get_matrix', 'manual__2022-07-23T01:22:13.378970+00:00', '--job-id', '12', '--raw', '--subdir', 'DAGS_FOLDER/mydag.py', '--cfg-path', '/tmp/tmpk7bhcba6', '--error-file', '/tmp/tmplraor17h']
[2022-07-22 21:22:17,401] {standard_task_runner.py:80} INFO - Job 12: Subtask get_matrix
[2022-07-22 21:22:17,425] {task_command.py:371} INFO - Running <TaskInstance: my_dag.get_matrix manual__2022-07-23T01:22:13.378970+00:00 [running]> on host DESKTOP-5GAFI6N.localdomain
[2022-07-22 21:22:17,455] {taskinstance.py:1589} INFO - Exporting the following env vars:
AIRFLOW_CTX_DAG_OWNER=airflow
AIRFLOW_CTX_DAG_ID=my_dag
AIRFLOW_CTX_TASK_ID=get_matrix
AIRFLOW_CTX_EXECUTION_DATE=2022-07-23T01:22:13.378970+00:00
AIRFLOW_CTX_TRY_NUMBER=1
AIRFLOW_CTX_DAG_RUN_ID=manual__2022-07-23T01:22:13.378970+00:00
[2022-07-22 21:22:17,456] {taskinstance.py:1909} ERROR - Task failed with exception
Traceback (most recent call last):
  File "/home/lemon/main/airflow/venv/lib/python3.8/site-packages/airflow/operators/python.py", line 171, in execute
    return_value = self.execute_callable()
  File "/home/lemon/main/airflow/venv/lib/python3.8/site-packages/airflow/operators/python.py", line 189, in execute_callable
    return self.python_callable(*self.op_args, **self.op_kwargs)
TypeError: confusion_matrix() missing 2 required positional arguments: 'y_true' and 'y_pred'
[2022-07-22 21:22:17,458] {taskinstance.py:1415} INFO - Marking task as FAILED. dag_id=my_dag, task_id=get_matrix, execution_date=20220723T012213, start_date=20220723T012217, end_date=20220723T012217
[2022-07-22 21:22:17,466] {standard_task_runner.py:92} ERROR - Failed to execute job 12 for task get_matrix (confusion_matrix() missing 2 required positional arguments: 'y_true' and 'y_pred'; 14925)
[2022-07-22 21:22:17,492] {local_task_job.py:156} INFO - Task exited with return code 1
[2022-07-22 21:22:17,502] {local_task_job.py:273} INFO - 0 downstream tasks scheduled from follow-on schedule check
