
2022-07-14 20:18:12,503 loglevel=INFO   Started server process [1688]
2022-07-14 20:18:12,503 loglevel=INFO   Waiting for application startup.
2022-07-14 20:18:12,504 loglevel=INFO   Application startup complete.
2022-07-14 20:18:20,899 loglevel=INFO   rid=P6T3XN request url=http://127.0.0.1:8000/ completed_in=0.00ms status_code=200
2022-07-14 20:18:20,986 loglevel=INFO   rid=5KPWI4 request url=http://127.0.0.1:8000/static/0041e69431bf872309d1aff628b6494f.jpg completed_in=50.05ms status_code=200
2022-07-14 20:18:28,374 loglevel=INFO   rid=EMEGCK request url=http://127.0.0.1:8000/docs completed_in=0.00ms status_code=200
2022-07-14 20:18:28,589 loglevel=INFO   rid=UT9XFJ request url=http://127.0.0.1:8000/openapi.json completed_in=4.00ms status_code=200
2022-07-14 20:18:51,624 loglevel=ERROR  Exception in ASGI application
Traceback (most recent call last):
  File "H:\Documents\GitHub\Assignment3\venv\lib\site-packages\anyio\streams\memory.py", line 94, in receive
    return self.receive_nowait()
  File "H:\Documents\GitHub\Assignment3\venv\lib\site-packages\anyio\streams\memory.py", line 89, in receive_nowait
    raise WouldBlock
anyio.WouldBlock

During handling of the above exception, another exception occurred:

Traceback (most recent call last):
  File "H:\Documents\GitHub\Assignment3\venv\lib\site-packages\starlette\middleware\base.py", line 43, in call_next
    message = await recv_stream.receive()
  File "H:\Documents\GitHub\Assignment3\venv\lib\site-packages\anyio\streams\memory.py", line 114, in receive
    raise EndOfStream
anyio.EndOfStream

During handling of the above exception, another exception occurred:

Traceback (most recent call last):
  File "H:\Documents\GitHub\Assignment3\venv\lib\site-packages\uvicorn\protocols\http\h11_impl.py", line 403, in run_asgi
    result = await app(self.scope, self.receive, self.send)
  File "H:\Documents\GitHub\Assignment3\venv\lib\site-packages\uvicorn\middleware\proxy_headers.py", line 78, in __call__
    return await self.app(scope, receive, send)
  File "H:\Documents\GitHub\Assignment3\venv\lib\site-packages\fastapi\applications.py", line 269, in __call__
    await super().__call__(scope, receive, send)
  File "H:\Documents\GitHub\Assignment3\venv\lib\site-packages\starlette\applications.py", line 124, in __call__
    await self.middleware_stack(scope, receive, send)
  File "H:\Documents\GitHub\Assignment3\venv\lib\site-packages\starlette\middleware\errors.py", line 184, in __call__
    raise exc
  File "H:\Documents\GitHub\Assignment3\venv\lib\site-packages\starlette\middleware\errors.py", line 162, in __call__
    await self.app(scope, receive, _send)
  File "H:\Documents\GitHub\Assignment3\venv\lib\site-packages\starlette\middleware\base.py", line 68, in __call__
    response = await self.dispatch_func(request, call_next)
  File "H:\Documents\GitHub\Assignment3\src\.\main.py", line 246, in log_requests
    response = await call_next(request)
  File "H:\Documents\GitHub\Assignment3\venv\lib\site-packages\starlette\middleware\base.py", line 46, in call_next
    raise app_exc
  File "H:\Documents\GitHub\Assignment3\venv\lib\site-packages\starlette\middleware\base.py", line 36, in coro
    await self.app(scope, request.receive, send_stream.send)
  File "H:\Documents\GitHub\Assignment3\venv\lib\site-packages\starlette\exceptions.py", line 93, in __call__
    raise exc
  File "H:\Documents\GitHub\Assignment3\venv\lib\site-packages\starlette\exceptions.py", line 82, in __call__
    await self.app(scope, receive, sender)
  File "H:\Documents\GitHub\Assignment3\venv\lib\site-packages\fastapi\middleware\asyncexitstack.py", line 21, in __call__
    raise e
  File "H:\Documents\GitHub\Assignment3\venv\lib\site-packages\fastapi\middleware\asyncexitstack.py", line 18, in __call__
    await self.app(scope, receive, send)
  File "H:\Documents\GitHub\Assignment3\venv\lib\site-packages\starlette\routing.py", line 670, in __call__
    await route.handle(scope, receive, send)
  File "H:\Documents\GitHub\Assignment3\venv\lib\site-packages\starlette\routing.py", line 266, in handle
    await self.app(scope, receive, send)
  File "H:\Documents\GitHub\Assignment3\venv\lib\site-packages\starlette\routing.py", line 65, in app
    response = await func(request)
  File "H:\Documents\GitHub\Assignment3\venv\lib\site-packages\fastapi\routing.py", line 227, in app
    raw_response = await run_endpoint_function(
  File "H:\Documents\GitHub\Assignment3\venv\lib\site-packages\fastapi\routing.py", line 160, in run_endpoint_function
    return await dependant.call(**values)
  File "H:\Documents\GitHub\Assignment3\src\.\main.py", line 192, in login_for_access_token
    user = authenticate_user(form_data.username, form_data.password)
  File "H:\Documents\GitHub\Assignment3\src\.\main.py", line 145, in authenticate_user
    if not verify_password(password, user.hashed_password):
  File "H:\Documents\GitHub\Assignment3\src\.\main.py", line 111, in verify_password
    return pwd_context.verify(plain_password, hashed_password)
  File "H:\Documents\GitHub\Assignment3\venv\lib\site-packages\passlib\context.py", line 2347, in verify
    return record.verify(secret, hash, **kwds)
  File "H:\Documents\GitHub\Assignment3\venv\lib\site-packages\passlib\utils\handlers.py", line 792, in verify
    return consteq(self._calc_checksum(secret), chk)
  File "H:\Documents\GitHub\Assignment3\venv\lib\site-packages\passlib\handlers\bcrypt.py", line 591, in _calc_checksum
    self._stub_requires_backend()
  File "H:\Documents\GitHub\Assignment3\venv\lib\site-packages\passlib\utils\handlers.py", line 2254, in _stub_requires_backend
    cls.set_backend()
  File "H:\Documents\GitHub\Assignment3\venv\lib\site-packages\passlib\utils\handlers.py", line 2156, in set_backend
    return owner.set_backend(name, dryrun=dryrun)
  File "H:\Documents\GitHub\Assignment3\venv\lib\site-packages\passlib\utils\handlers.py", line 2176, in set_backend
    raise default_error
passlib.exc.MissingBackendError: bcrypt: no backends available -- recommend you install one (e.g. 'pip install bcrypt')
2022-07-14 20:19:13,272 loglevel=INFO   Shutting down
2022-07-14 20:19:13,382 loglevel=INFO   Waiting for application shutdown.
2022-07-14 20:19:13,382 loglevel=INFO   Application shutdown complete.
2022-07-14 20:19:13,383 loglevel=INFO   Finished server process [1688]
2022-07-14 20:19:25,468 loglevel=INFO   Started server process [6768]
2022-07-14 20:19:25,468 loglevel=INFO   Waiting for application startup.
2022-07-14 20:19:25,469 loglevel=INFO   Application startup complete.
2022-07-14 20:19:28,630 loglevel=INFO   rid=OI5GHN request url=http://127.0.0.1:8000/docs completed_in=0.00ms status_code=200
2022-07-14 20:19:28,761 loglevel=INFO   rid=W7NXSU request url=http://127.0.0.1:8000/openapi.json completed_in=4.00ms status_code=200
2022-07-14 20:19:34,765 loglevel=INFO   rid=STB7E5 request url=http://127.0.0.1:8000/token completed_in=225.21ms status_code=200
2022-07-14 20:21:06,960 loglevel=INFO   Started server process [7312]
2022-07-14 20:21:06,961 loglevel=INFO   Waiting for application startup.
2022-07-14 20:21:06,961 loglevel=INFO   Application startup complete.
2022-07-14 20:22:56,928 loglevel=INFO   Started server process [15576]
2022-07-14 20:22:56,929 loglevel=INFO   Waiting for application startup.
2022-07-14 20:22:56,929 loglevel=INFO   Application startup complete.
2022-07-14 20:22:58,594 loglevel=INFO   rid=TAZGE9 request url=http://127.0.0.1:8000/docs completed_in=1.00ms status_code=200
2022-07-14 20:22:58,669 loglevel=INFO   rid=H9F6ZV request url=http://127.0.0.1:8000/openapi.json completed_in=4.00ms status_code=200
2022-07-14 20:23:03,590 loglevel=INFO   rid=NFOBPD request url=http://127.0.0.1:8000/token completed_in=226.21ms status_code=200
2022-07-14 20:23:14,162 loglevel=ERROR  Exception in ASGI application
Traceback (most recent call last):
  File "H:\Documents\GitHub\Assignment3\venv\lib\site-packages\anyio\streams\memory.py", line 94, in receive
    return self.receive_nowait()
  File "H:\Documents\GitHub\Assignment3\venv\lib\site-packages\anyio\streams\memory.py", line 89, in receive_nowait
    raise WouldBlock
anyio.WouldBlock

During handling of the above exception, another exception occurred:

Traceback (most recent call last):
  File "H:\Documents\GitHub\Assignment3\venv\lib\site-packages\starlette\middleware\base.py", line 43, in call_next
    message = await recv_stream.receive()
  File "H:\Documents\GitHub\Assignment3\venv\lib\site-packages\anyio\streams\memory.py", line 114, in receive
    raise EndOfStream
anyio.EndOfStream

During handling of the above exception, another exception occurred:

Traceback (most recent call last):
  File "H:\Documents\GitHub\Assignment3\venv\lib\site-packages\uvicorn\protocols\http\h11_impl.py", line 403, in run_asgi
    result = await app(self.scope, self.receive, self.send)
  File "H:\Documents\GitHub\Assignment3\venv\lib\site-packages\uvicorn\middleware\proxy_headers.py", line 78, in __call__
    return await self.app(scope, receive, send)
  File "H:\Documents\GitHub\Assignment3\venv\lib\site-packages\fastapi\applications.py", line 269, in __call__
    await super().__call__(scope, receive, send)
  File "H:\Documents\GitHub\Assignment3\venv\lib\site-packages\starlette\applications.py", line 124, in __call__
    await self.middleware_stack(scope, receive, send)
  File "H:\Documents\GitHub\Assignment3\venv\lib\site-packages\starlette\middleware\errors.py", line 184, in __call__
    raise exc
  File "H:\Documents\GitHub\Assignment3\venv\lib\site-packages\starlette\middleware\errors.py", line 162, in __call__
    await self.app(scope, receive, _send)
  File "H:\Documents\GitHub\Assignment3\venv\lib\site-packages\starlette\middleware\base.py", line 68, in __call__
    response = await self.dispatch_func(request, call_next)
  File "H:\Documents\GitHub\Assignment3\src\.\main.py", line 245, in log_requests
    response = await call_next(request)
  File "H:\Documents\GitHub\Assignment3\venv\lib\site-packages\starlette\middleware\base.py", line 46, in call_next
    raise app_exc
  File "H:\Documents\GitHub\Assignment3\venv\lib\site-packages\starlette\middleware\base.py", line 36, in coro
    await self.app(scope, request.receive, send_stream.send)
  File "H:\Documents\GitHub\Assignment3\venv\lib\site-packages\starlette\exceptions.py", line 93, in __call__
    raise exc
  File "H:\Documents\GitHub\Assignment3\venv\lib\site-packages\starlette\exceptions.py", line 82, in __call__
    await self.app(scope, receive, sender)
  File "H:\Documents\GitHub\Assignment3\venv\lib\site-packages\fastapi\middleware\asyncexitstack.py", line 21, in __call__
    raise e
  File "H:\Documents\GitHub\Assignment3\venv\lib\site-packages\fastapi\middleware\asyncexitstack.py", line 18, in __call__
    await self.app(scope, receive, send)
  File "H:\Documents\GitHub\Assignment3\venv\lib\site-packages\starlette\routing.py", line 670, in __call__
    await route.handle(scope, receive, send)
  File "H:\Documents\GitHub\Assignment3\venv\lib\site-packages\starlette\routing.py", line 266, in handle
    await self.app(scope, receive, send)
  File "H:\Documents\GitHub\Assignment3\venv\lib\site-packages\starlette\routing.py", line 65, in app
    response = await func(request)
  File "H:\Documents\GitHub\Assignment3\venv\lib\site-packages\fastapi\routing.py", line 227, in app
    raw_response = await run_endpoint_function(
  File "H:\Documents\GitHub\Assignment3\venv\lib\site-packages\fastapi\routing.py", line 160, in run_endpoint_function
    return await dependant.call(**values)
  File "H:\Documents\GitHub\Assignment3\src\.\main.py", line 302, in qualityinspection
    response = test_model.qualityinspection(file)
  File "H:\Documents\GitHub\Assignment3\src\api_functions\test_model.py", line 18, in qualityinspection
    img = keras.utils.load_img(file, target_size = (256, 256))
  File "H:\Documents\GitHub\Assignment3\venv\lib\site-packages\keras\utils\image_utils.py", line 396, in load_img
    raise TypeError('path should be path-like or io.BytesIO'
TypeError: path should be path-like or io.BytesIO, not <class 'starlette.datastructures.UploadFile'>
2022-07-14 20:24:55,218 loglevel=INFO   Started server process [5992]
2022-07-14 20:24:55,219 loglevel=INFO   Waiting for application startup.
2022-07-14 20:24:55,219 loglevel=INFO   Application startup complete.
2022-07-14 20:24:57,079 loglevel=INFO   Shutting down
2022-07-14 20:24:57,187 loglevel=INFO   Waiting for application shutdown.
2022-07-14 20:24:57,187 loglevel=INFO   Application shutdown complete.
2022-07-14 20:24:57,188 loglevel=INFO   Finished server process [5992]
2022-07-14 20:33:38,844 loglevel=INFO   Started server process [1896]
2022-07-14 20:33:38,845 loglevel=INFO   Waiting for application startup.
2022-07-14 20:33:38,845 loglevel=INFO   Application startup complete.
2022-07-14 20:33:44,832 loglevel=INFO   rid=RLLV0K request url=http://127.0.0.1:8000/docs completed_in=0.00ms status_code=200
2022-07-14 20:33:44,953 loglevel=INFO   rid=RQB75S request url=http://127.0.0.1:8000/openapi.json completed_in=4.00ms status_code=200
2022-07-14 20:33:56,714 loglevel=INFO   rid=YPU4T4 request url=http://127.0.0.1:8000/token completed_in=223.20ms status_code=200
2022-07-14 20:34:03,510 loglevel=INFO   rid=T21DV4 request url=http://127.0.0.1:8000/files/ completed_in=69.05ms status_code=200
2022-07-14 20:35:46,089 loglevel=INFO   Started server process [5080]
2022-07-14 20:35:46,089 loglevel=INFO   Waiting for application startup.
2022-07-14 20:35:46,090 loglevel=INFO   Application startup complete.
2022-07-14 20:35:46,843 loglevel=INFO   rid=VVEK6C request url=http://127.0.0.1:8000/docs completed_in=0.00ms status_code=200
2022-07-14 20:35:46,976 loglevel=INFO   rid=D56ZXX request url=http://127.0.0.1:8000/openapi.json completed_in=4.00ms status_code=200
2022-07-14 20:43:32,492 loglevel=INFO   Started server process [8524]
2022-07-14 20:43:32,492 loglevel=INFO   Waiting for application startup.
2022-07-14 20:43:32,493 loglevel=INFO   Application startup complete.
2022-07-14 20:44:09,608 loglevel=INFO   Started server process [2272]
2022-07-14 20:44:09,609 loglevel=INFO   Waiting for application startup.
2022-07-14 20:44:09,609 loglevel=INFO   Application startup complete.
2022-07-14 20:44:12,698 loglevel=INFO   rid=LBLWJK request url=http://127.0.0.1:8000/docs completed_in=1.00ms status_code=200
2022-07-14 20:44:12,807 loglevel=INFO   rid=I8QMDK request url=http://127.0.0.1:8000/openapi.json completed_in=4.00ms status_code=200
2022-07-14 20:44:18,231 loglevel=INFO   rid=5L9T4N request url=http://127.0.0.1:8000/token completed_in=225.20ms status_code=200
2022-07-14 20:44:42,001 loglevel=ERROR  Exception in ASGI application
Traceback (most recent call last):
  File "H:\Documents\GitHub\Assignment3\venv\lib\site-packages\anyio\streams\memory.py", line 94, in receive
    return self.receive_nowait()
  File "H:\Documents\GitHub\Assignment3\venv\lib\site-packages\anyio\streams\memory.py", line 89, in receive_nowait
    raise WouldBlock
anyio.WouldBlock

During handling of the above exception, another exception occurred:

Traceback (most recent call last):
  File "H:\Documents\GitHub\Assignment3\venv\lib\site-packages\starlette\middleware\base.py", line 43, in call_next
    message = await recv_stream.receive()
  File "H:\Documents\GitHub\Assignment3\venv\lib\site-packages\anyio\streams\memory.py", line 114, in receive
    raise EndOfStream
anyio.EndOfStream

During handling of the above exception, another exception occurred:

Traceback (most recent call last):
  File "H:\Documents\GitHub\Assignment3\venv\lib\site-packages\uvicorn\protocols\http\h11_impl.py", line 403, in run_asgi
    result = await app(self.scope, self.receive, self.send)
  File "H:\Documents\GitHub\Assignment3\venv\lib\site-packages\uvicorn\middleware\proxy_headers.py", line 78, in __call__
    return await self.app(scope, receive, send)
  File "H:\Documents\GitHub\Assignment3\venv\lib\site-packages\fastapi\applications.py", line 269, in __call__
    await super().__call__(scope, receive, send)
  File "H:\Documents\GitHub\Assignment3\venv\lib\site-packages\starlette\applications.py", line 124, in __call__
    await self.middleware_stack(scope, receive, send)
  File "H:\Documents\GitHub\Assignment3\venv\lib\site-packages\starlette\middleware\errors.py", line 184, in __call__
    raise exc
  File "H:\Documents\GitHub\Assignment3\venv\lib\site-packages\starlette\middleware\errors.py", line 162, in __call__
    await self.app(scope, receive, _send)
  File "H:\Documents\GitHub\Assignment3\venv\lib\site-packages\starlette\middleware\base.py", line 68, in __call__
    response = await self.dispatch_func(request, call_next)
  File "H:\Documents\GitHub\Assignment3\src\.\main.py", line 245, in log_requests
    response = await call_next(request)
  File "H:\Documents\GitHub\Assignment3\venv\lib\site-packages\starlette\middleware\base.py", line 46, in call_next
    raise app_exc
  File "H:\Documents\GitHub\Assignment3\venv\lib\site-packages\starlette\middleware\base.py", line 36, in coro
    await self.app(scope, request.receive, send_stream.send)
  File "H:\Documents\GitHub\Assignment3\venv\lib\site-packages\starlette\exceptions.py", line 93, in __call__
    raise exc
  File "H:\Documents\GitHub\Assignment3\venv\lib\site-packages\starlette\exceptions.py", line 82, in __call__
    await self.app(scope, receive, sender)
  File "H:\Documents\GitHub\Assignment3\venv\lib\site-packages\fastapi\middleware\asyncexitstack.py", line 21, in __call__
    raise e
  File "H:\Documents\GitHub\Assignment3\venv\lib\site-packages\fastapi\middleware\asyncexitstack.py", line 18, in __call__
    await self.app(scope, receive, send)
  File "H:\Documents\GitHub\Assignment3\venv\lib\site-packages\starlette\routing.py", line 670, in __call__
    await route.handle(scope, receive, send)
  File "H:\Documents\GitHub\Assignment3\venv\lib\site-packages\starlette\routing.py", line 266, in handle
    await self.app(scope, receive, send)
  File "H:\Documents\GitHub\Assignment3\venv\lib\site-packages\starlette\routing.py", line 65, in app
    response = await func(request)
  File "H:\Documents\GitHub\Assignment3\venv\lib\site-packages\fastapi\routing.py", line 227, in app
    raw_response = await run_endpoint_function(
  File "H:\Documents\GitHub\Assignment3\venv\lib\site-packages\fastapi\routing.py", line 160, in run_endpoint_function
    return await dependant.call(**values)
  File "H:\Documents\GitHub\Assignment3\src\.\main.py", line 303, in qualityinspection
    response = test_model.qualityinspection(files)
  File "H:\Documents\GitHub\Assignment3\src\api_functions\test_model.py", line 24, in qualityinspection
    img = Image.open(io.BytesIO(file))
TypeError: a bytes-like object is required, not 'list'
2022-07-14 20:45:37,682 loglevel=INFO   Started server process [14236]
2022-07-14 20:45:37,682 loglevel=INFO   Waiting for application startup.
2022-07-14 20:45:37,683 loglevel=INFO   Application startup complete.
2022-07-14 20:45:40,393 loglevel=INFO   rid=DF4JC7 request url=http://127.0.0.1:8000/docs completed_in=0.00ms status_code=200
2022-07-14 20:45:40,529 loglevel=INFO   rid=CW2G4S request url=http://127.0.0.1:8000/openapi.json completed_in=3.00ms status_code=200
2022-07-14 20:45:45,431 loglevel=INFO   rid=RD7B3B request url=http://127.0.0.1:8000/token completed_in=223.20ms status_code=200
2022-07-14 20:45:52,657 loglevel=ERROR  Exception in ASGI application
Traceback (most recent call last):
  File "H:\Documents\GitHub\Assignment3\venv\lib\site-packages\starlette\middleware\base.py", line 43, in call_next
    message = await recv_stream.receive()
  File "H:\Documents\GitHub\Assignment3\venv\lib\site-packages\anyio\streams\memory.py", line 94, in receive
    return self.receive_nowait()
  File "H:\Documents\GitHub\Assignment3\venv\lib\site-packages\anyio\streams\memory.py", line 87, in receive_nowait
    raise EndOfStream
anyio.EndOfStream

During handling of the above exception, another exception occurred:

Traceback (most recent call last):
  File "H:\Documents\GitHub\Assignment3\venv\lib\site-packages\uvicorn\protocols\http\h11_impl.py", line 403, in run_asgi
    result = await app(self.scope, self.receive, self.send)
  File "H:\Documents\GitHub\Assignment3\venv\lib\site-packages\uvicorn\middleware\proxy_headers.py", line 78, in __call__
    return await self.app(scope, receive, send)
  File "H:\Documents\GitHub\Assignment3\venv\lib\site-packages\fastapi\applications.py", line 269, in __call__
    await super().__call__(scope, receive, send)
  File "H:\Documents\GitHub\Assignment3\venv\lib\site-packages\starlette\applications.py", line 124, in __call__
    await self.middleware_stack(scope, receive, send)
  File "H:\Documents\GitHub\Assignment3\venv\lib\site-packages\starlette\middleware\errors.py", line 184, in __call__
    raise exc
  File "H:\Documents\GitHub\Assignment3\venv\lib\site-packages\starlette\middleware\errors.py", line 162, in __call__
    await self.app(scope, receive, _send)
  File "H:\Documents\GitHub\Assignment3\venv\lib\site-packages\starlette\middleware\base.py", line 68, in __call__
    response = await self.dispatch_func(request, call_next)
  File "H:\Documents\GitHub\Assignment3\src\.\main.py", line 245, in log_requests
    response = await call_next(request)
  File "H:\Documents\GitHub\Assignment3\venv\lib\site-packages\starlette\middleware\base.py", line 46, in call_next
    raise app_exc
  File "H:\Documents\GitHub\Assignment3\venv\lib\site-packages\starlette\middleware\base.py", line 36, in coro
    await self.app(scope, request.receive, send_stream.send)
  File "H:\Documents\GitHub\Assignment3\venv\lib\site-packages\starlette\exceptions.py", line 93, in __call__
    raise exc
  File "H:\Documents\GitHub\Assignment3\venv\lib\site-packages\starlette\exceptions.py", line 82, in __call__
    await self.app(scope, receive, sender)
  File "H:\Documents\GitHub\Assignment3\venv\lib\site-packages\fastapi\middleware\asyncexitstack.py", line 21, in __call__
    raise e
  File "H:\Documents\GitHub\Assignment3\venv\lib\site-packages\fastapi\middleware\asyncexitstack.py", line 18, in __call__
    await self.app(scope, receive, send)
  File "H:\Documents\GitHub\Assignment3\venv\lib\site-packages\starlette\routing.py", line 670, in __call__
    await route.handle(scope, receive, send)
  File "H:\Documents\GitHub\Assignment3\venv\lib\site-packages\starlette\routing.py", line 266, in handle
    await self.app(scope, receive, send)
  File "H:\Documents\GitHub\Assignment3\venv\lib\site-packages\starlette\routing.py", line 65, in app
    response = await func(request)
  File "H:\Documents\GitHub\Assignment3\venv\lib\site-packages\fastapi\routing.py", line 227, in app
    raw_response = await run_endpoint_function(
  File "H:\Documents\GitHub\Assignment3\venv\lib\site-packages\fastapi\routing.py", line 160, in run_endpoint_function
    return await dependant.call(**values)
  File "H:\Documents\GitHub\Assignment3\src\.\main.py", line 303, in qualityinspection
    response = test_model.qualityinspection(file)
  File "H:\Documents\GitHub\Assignment3\src\api_functions\test_model.py", line 27, in qualityinspection
    img = Image.img_to_array(img)
  File "H:\Documents\GitHub\Assignment3\venv\lib\site-packages\PIL\Image.py", line 76, in __getattr__
    raise AttributeError(f"module '{__name__}' has no attribute '{name}'")
AttributeError: module 'PIL.Image' has no attribute 'img_to_array'
2022-07-14 20:47:09,953 loglevel=INFO   Started server process [14192]
2022-07-14 20:47:09,954 loglevel=INFO   Waiting for application startup.
2022-07-14 20:47:09,954 loglevel=INFO   Application startup complete.
2022-07-14 20:47:14,456 loglevel=ERROR  Exception in ASGI application
Traceback (most recent call last):
  File "H:\Documents\GitHub\Assignment3\venv\lib\site-packages\uvicorn\protocols\http\h11_impl.py", line 403, in run_asgi
    result = await app(self.scope, self.receive, self.send)
  File "H:\Documents\GitHub\Assignment3\venv\lib\site-packages\uvicorn\middleware\proxy_headers.py", line 78, in __call__
    return await self.app(scope, receive, send)
  File "H:\Documents\GitHub\Assignment3\venv\lib\site-packages\fastapi\applications.py", line 269, in __call__
    await super().__call__(scope, receive, send)
  File "H:\Documents\GitHub\Assignment3\venv\lib\site-packages\starlette\applications.py", line 124, in __call__
    await self.middleware_stack(scope, receive, send)
  File "H:\Documents\GitHub\Assignment3\venv\lib\site-packages\starlette\middleware\errors.py", line 184, in __call__
    raise exc
  File "H:\Documents\GitHub\Assignment3\venv\lib\site-packages\starlette\middleware\errors.py", line 162, in __call__
    await self.app(scope, receive, _send)
  File "H:\Documents\GitHub\Assignment3\venv\lib\site-packages\starlette\middleware\base.py", line 68, in __call__
    response = await self.dispatch_func(request, call_next)
  File "H:\Documents\GitHub\Assignment3\src\.\main.py", line 245, in log_requests
    response = await call_next(request)
  File "H:\Documents\GitHub\Assignment3\venv\lib\site-packages\starlette\middleware\base.py", line 46, in call_next
    raise app_exc
  File "H:\Documents\GitHub\Assignment3\venv\lib\site-packages\starlette\middleware\base.py", line 36, in coro
    await self.app(scope, request.receive, send_stream.send)
  File "H:\Documents\GitHub\Assignment3\venv\lib\site-packages\starlette\exceptions.py", line 93, in __call__
    raise exc
  File "H:\Documents\GitHub\Assignment3\venv\lib\site-packages\starlette\exceptions.py", line 82, in __call__
    await self.app(scope, receive, sender)
  File "H:\Documents\GitHub\Assignment3\venv\lib\site-packages\fastapi\middleware\asyncexitstack.py", line 21, in __call__
    raise e
  File "H:\Documents\GitHub\Assignment3\venv\lib\site-packages\fastapi\middleware\asyncexitstack.py", line 18, in __call__
    await self.app(scope, receive, send)
  File "H:\Documents\GitHub\Assignment3\venv\lib\site-packages\starlette\routing.py", line 670, in __call__
    await route.handle(scope, receive, send)
  File "H:\Documents\GitHub\Assignment3\venv\lib\site-packages\starlette\routing.py", line 266, in handle
    await self.app(scope, receive, send)
  File "H:\Documents\GitHub\Assignment3\venv\lib\site-packages\starlette\routing.py", line 65, in app
    response = await func(request)
  File "H:\Documents\GitHub\Assignment3\venv\lib\site-packages\fastapi\routing.py", line 227, in app
    raw_response = await run_endpoint_function(
  File "H:\Documents\GitHub\Assignment3\venv\lib\site-packages\fastapi\routing.py", line 160, in run_endpoint_function
    return await dependant.call(**values)
  File "H:\Documents\GitHub\Assignment3\src\.\main.py", line 303, in qualityinspection
    response = test_model.qualityinspection(file)
  File "H:\Documents\GitHub\Assignment3\src\api_functions\test_model.py", line 28, in qualityinspection
    prediction = model.predict(img)
  File "H:\Documents\GitHub\Assignment3\venv\lib\site-packages\keras\utils\traceback_utils.py", line 67, in error_handler
    raise e.with_traceback(filtered_tb) from None
  File "C:\Users\79972\AppData\Local\Temp\__autograph_generated_file0e7gjhow.py", line 15, in tf__predict_function
    retval_ = ag__.converted_call(ag__.ld(step_function), (ag__.ld(self), ag__.ld(iterator)), None, fscope)
ValueError: in user code:

    File "H:\Documents\GitHub\Assignment3\venv\lib\site-packages\keras\engine\training.py", line 1845, in predict_function  *
        return step_function(self, iterator)
    File "H:\Documents\GitHub\Assignment3\venv\lib\site-packages\keras\engine\training.py", line 1834, in step_function  **
        outputs = model.distribute_strategy.run(run_step, args=(data,))
    File "H:\Documents\GitHub\Assignment3\venv\lib\site-packages\keras\engine\training.py", line 1823, in run_step  **
        outputs = model.predict_step(data)
    File "H:\Documents\GitHub\Assignment3\venv\lib\site-packages\keras\engine\training.py", line 1791, in predict_step
        return self(x, training=False)
    File "H:\Documents\GitHub\Assignment3\venv\lib\site-packages\keras\utils\traceback_utils.py", line 67, in error_handler
        raise e.with_traceback(filtered_tb) from None
    File "H:\Documents\GitHub\Assignment3\venv\lib\site-packages\keras\engine\input_spec.py", line 264, in assert_input_compatibility
        raise ValueError(f'Input {input_index} of layer "{layer_name}" is '

    ValueError: Input 0 of layer "sequential" is incompatible with the layer: expected shape=(None, 256, 256, 3), found shape=(32, 256, 3)

2022-07-14 20:48:11,023 loglevel=INFO   Started server process [8912]
2022-07-14 20:48:11,023 loglevel=INFO   Waiting for application startup.
2022-07-14 20:48:11,024 loglevel=INFO   Application startup complete.
2022-07-14 20:48:18,800 loglevel=INFO   rid=CKQ8XL request url=http://127.0.0.1:8000/qualityinspection/ completed_in=2929.19ms status_code=200
2022-07-14 20:48:51,115 loglevel=INFO   rid=6WI211 request url=http://127.0.0.1:8000/qualityinspection/ completed_in=2920.24ms status_code=200
2022-07-14 20:49:17,006 loglevel=INFO   rid=EIQSL6 request url=http://127.0.0.1:8000/qualityinspection/ completed_in=2892.70ms status_code=200
2022-07-14 20:56:54,945 loglevel=INFO   Started server process [9972]
2022-07-14 20:56:54,946 loglevel=INFO   Waiting for application startup.
2022-07-14 20:56:54,947 loglevel=INFO   Application startup complete.
2022-07-14 20:58:23,304 loglevel=INFO   Started server process [15008]
2022-07-14 20:58:23,304 loglevel=INFO   Waiting for application startup.
2022-07-14 20:58:23,305 loglevel=INFO   Application startup complete.
2022-07-14 20:58:29,042 loglevel=ERROR  Exception in ASGI application
Traceback (most recent call last):
  File "H:\Documents\GitHub\Assignment3\venv\lib\site-packages\anyio\streams\memory.py", line 94, in receive
    return self.receive_nowait()
  File "H:\Documents\GitHub\Assignment3\venv\lib\site-packages\anyio\streams\memory.py", line 89, in receive_nowait
    raise WouldBlock
anyio.WouldBlock

During handling of the above exception, another exception occurred:

Traceback (most recent call last):
  File "H:\Documents\GitHub\Assignment3\venv\lib\site-packages\starlette\middleware\base.py", line 43, in call_next
    message = await recv_stream.receive()
  File "H:\Documents\GitHub\Assignment3\venv\lib\site-packages\anyio\streams\memory.py", line 114, in receive
    raise EndOfStream
anyio.EndOfStream

During handling of the above exception, another exception occurred:

Traceback (most recent call last):
  File "H:\Documents\GitHub\Assignment3\venv\lib\site-packages\uvicorn\protocols\http\h11_impl.py", line 403, in run_asgi
    result = await app(self.scope, self.receive, self.send)
  File "H:\Documents\GitHub\Assignment3\venv\lib\site-packages\uvicorn\middleware\proxy_headers.py", line 78, in __call__
    return await self.app(scope, receive, send)
  File "H:\Documents\GitHub\Assignment3\venv\lib\site-packages\fastapi\applications.py", line 269, in __call__
    await super().__call__(scope, receive, send)
  File "H:\Documents\GitHub\Assignment3\venv\lib\site-packages\starlette\applications.py", line 124, in __call__
    await self.middleware_stack(scope, receive, send)
  File "H:\Documents\GitHub\Assignment3\venv\lib\site-packages\starlette\middleware\errors.py", line 184, in __call__
    raise exc
  File "H:\Documents\GitHub\Assignment3\venv\lib\site-packages\starlette\middleware\errors.py", line 162, in __call__
    await self.app(scope, receive, _send)
  File "H:\Documents\GitHub\Assignment3\venv\lib\site-packages\starlette\middleware\base.py", line 68, in __call__
    response = await self.dispatch_func(request, call_next)
  File "H:\Documents\GitHub\Assignment3\src\.\main.py", line 245, in log_requests
    response = await call_next(request)
  File "H:\Documents\GitHub\Assignment3\venv\lib\site-packages\starlette\middleware\base.py", line 46, in call_next
    raise app_exc
  File "H:\Documents\GitHub\Assignment3\venv\lib\site-packages\starlette\middleware\base.py", line 36, in coro
    await self.app(scope, request.receive, send_stream.send)
  File "H:\Documents\GitHub\Assignment3\venv\lib\site-packages\starlette\exceptions.py", line 93, in __call__
    raise exc
  File "H:\Documents\GitHub\Assignment3\venv\lib\site-packages\starlette\exceptions.py", line 82, in __call__
    await self.app(scope, receive, sender)
  File "H:\Documents\GitHub\Assignment3\venv\lib\site-packages\fastapi\middleware\asyncexitstack.py", line 21, in __call__
    raise e
  File "H:\Documents\GitHub\Assignment3\venv\lib\site-packages\fastapi\middleware\asyncexitstack.py", line 18, in __call__
    await self.app(scope, receive, send)
  File "H:\Documents\GitHub\Assignment3\venv\lib\site-packages\starlette\routing.py", line 670, in __call__
    await route.handle(scope, receive, send)
  File "H:\Documents\GitHub\Assignment3\venv\lib\site-packages\starlette\routing.py", line 266, in handle
    await self.app(scope, receive, send)
  File "H:\Documents\GitHub\Assignment3\venv\lib\site-packages\starlette\routing.py", line 65, in app
    response = await func(request)
  File "H:\Documents\GitHub\Assignment3\venv\lib\site-packages\fastapi\routing.py", line 227, in app
    raw_response = await run_endpoint_function(
  File "H:\Documents\GitHub\Assignment3\venv\lib\site-packages\fastapi\routing.py", line 160, in run_endpoint_function
    return await dependant.call(**values)
  File "H:\Documents\GitHub\Assignment3\src\.\main.py", line 301, in qualityinspection
    filename = file.filename
AttributeError: 'bytes' object has no attribute 'filename'
2022-07-14 21:00:03,794 loglevel=INFO   Started server process [13716]
2022-07-14 21:00:03,794 loglevel=INFO   Waiting for application startup.
2022-07-14 21:00:03,795 loglevel=INFO   Application startup complete.
2022-07-14 21:00:09,737 loglevel=INFO   rid=AN6XZD request url=http://127.0.0.1:8000/docs completed_in=0.00ms status_code=200
2022-07-14 21:00:09,808 loglevel=INFO   rid=HHYFO9 request url=http://127.0.0.1:8000/openapi.json completed_in=3.00ms status_code=200
2022-07-14 21:00:14,608 loglevel=INFO   rid=GYJSZI request url=http://127.0.0.1:8000/token completed_in=223.20ms status_code=200
2022-07-14 21:02:02,170 loglevel=INFO   Started server process [15704]
2022-07-14 21:02:02,170 loglevel=INFO   Waiting for application startup.
2022-07-14 21:02:02,171 loglevel=INFO   Application startup complete.
2022-07-14 21:03:02,548 loglevel=INFO   Started server process [3912]
2022-07-14 21:03:02,548 loglevel=INFO   Waiting for application startup.
2022-07-14 21:03:02,549 loglevel=INFO   Application startup complete.
2022-07-14 21:03:03,180 loglevel=INFO   rid=DE9NZ2 request url=http://127.0.0.1:8000/docs completed_in=0.00ms status_code=200
2022-07-14 21:03:03,253 loglevel=INFO   rid=27G97O request url=http://127.0.0.1:8000/openapi.json completed_in=3.00ms status_code=200
2022-07-14 21:03:08,865 loglevel=INFO   rid=1NPQ6I request url=http://127.0.0.1:8000/token completed_in=225.20ms status_code=200
2022-07-14 21:03:41,219 loglevel=INFO   rid=5BOG5K request url=http://127.0.0.1:8000/qualityinspection/?filename=fgsfg completed_in=2912.44ms status_code=200
2022-07-14 21:06:01,656 loglevel=INFO   Started server process [14148]
2022-07-14 21:06:01,657 loglevel=INFO   Waiting for application startup.
2022-07-14 21:06:01,657 loglevel=INFO   Application startup complete.
2022-07-14 21:06:04,497 loglevel=ERROR  Exception in ASGI application
Traceback (most recent call last):
  File "H:\Documents\GitHub\Assignment3\venv\lib\site-packages\starlette\middleware\base.py", line 43, in call_next
    message = await recv_stream.receive()
  File "H:\Documents\GitHub\Assignment3\venv\lib\site-packages\anyio\streams\memory.py", line 94, in receive
    return self.receive_nowait()
  File "H:\Documents\GitHub\Assignment3\venv\lib\site-packages\anyio\streams\memory.py", line 87, in receive_nowait
    raise EndOfStream
anyio.EndOfStream

During handling of the above exception, another exception occurred:

Traceback (most recent call last):
  File "H:\Documents\GitHub\Assignment3\venv\lib\site-packages\uvicorn\protocols\http\h11_impl.py", line 403, in run_asgi
    result = await app(self.scope, self.receive, self.send)
  File "H:\Documents\GitHub\Assignment3\venv\lib\site-packages\uvicorn\middleware\proxy_headers.py", line 78, in __call__
    return await self.app(scope, receive, send)
  File "H:\Documents\GitHub\Assignment3\venv\lib\site-packages\fastapi\applications.py", line 269, in __call__
    await super().__call__(scope, receive, send)
  File "H:\Documents\GitHub\Assignment3\venv\lib\site-packages\starlette\applications.py", line 124, in __call__
    await self.middleware_stack(scope, receive, send)
  File "H:\Documents\GitHub\Assignment3\venv\lib\site-packages\starlette\middleware\errors.py", line 184, in __call__
    raise exc
  File "H:\Documents\GitHub\Assignment3\venv\lib\site-packages\starlette\middleware\errors.py", line 162, in __call__
    await self.app(scope, receive, _send)
  File "H:\Documents\GitHub\Assignment3\venv\lib\site-packages\starlette\middleware\base.py", line 68, in __call__
    response = await self.dispatch_func(request, call_next)
  File "H:\Documents\GitHub\Assignment3\src\.\main.py", line 245, in log_requests
    response = await call_next(request)
  File "H:\Documents\GitHub\Assignment3\venv\lib\site-packages\starlette\middleware\base.py", line 46, in call_next
    raise app_exc
  File "H:\Documents\GitHub\Assignment3\venv\lib\site-packages\starlette\middleware\base.py", line 36, in coro
    await self.app(scope, request.receive, send_stream.send)
  File "H:\Documents\GitHub\Assignment3\venv\lib\site-packages\starlette\exceptions.py", line 93, in __call__
    raise exc
  File "H:\Documents\GitHub\Assignment3\venv\lib\site-packages\starlette\exceptions.py", line 82, in __call__
    await self.app(scope, receive, sender)
  File "H:\Documents\GitHub\Assignment3\venv\lib\site-packages\fastapi\middleware\asyncexitstack.py", line 21, in __call__
    raise e
  File "H:\Documents\GitHub\Assignment3\venv\lib\site-packages\fastapi\middleware\asyncexitstack.py", line 18, in __call__
    await self.app(scope, receive, send)
  File "H:\Documents\GitHub\Assignment3\venv\lib\site-packages\starlette\routing.py", line 670, in __call__
    await route.handle(scope, receive, send)
  File "H:\Documents\GitHub\Assignment3\venv\lib\site-packages\starlette\routing.py", line 266, in handle
    await self.app(scope, receive, send)
  File "H:\Documents\GitHub\Assignment3\venv\lib\site-packages\starlette\routing.py", line 65, in app
    response = await func(request)
  File "H:\Documents\GitHub\Assignment3\venv\lib\site-packages\fastapi\routing.py", line 227, in app
    raw_response = await run_endpoint_function(
  File "H:\Documents\GitHub\Assignment3\venv\lib\site-packages\fastapi\routing.py", line 160, in run_endpoint_function
    return await dependant.call(**values)
  File "H:\Documents\GitHub\Assignment3\src\.\main.py", line 305, in qualityinspection
    response = test_model.qualityinspection(file)
TypeError: qualityinspection() missing 1 required positional argument: 'file'
2022-07-14 21:06:06,419 loglevel=INFO   rid=K6RGXY request url=http://127.0.0.1:8000/docs completed_in=0.00ms status_code=200
2022-07-14 21:06:06,540 loglevel=INFO   rid=W7380B request url=http://127.0.0.1:8000/openapi.json completed_in=3.00ms status_code=200
2022-07-14 21:06:13,406 loglevel=INFO   rid=TJH9M3 request url=http://127.0.0.1:8000/token completed_in=223.09ms status_code=200
2022-07-14 21:06:31,767 loglevel=INFO   Started server process [11172]
2022-07-14 21:06:31,767 loglevel=INFO   Waiting for application startup.
2022-07-14 21:06:31,768 loglevel=INFO   Application startup complete.
2022-07-14 21:06:32,237 loglevel=INFO   rid=62Z0I1 request url=http://127.0.0.1:8000/docs completed_in=0.00ms status_code=200
2022-07-14 21:06:32,369 loglevel=INFO   rid=PNCPPI request url=http://127.0.0.1:8000/openapi.json completed_in=4.00ms status_code=200
2022-07-14 21:06:37,523 loglevel=INFO   rid=U5Y3R7 request url=http://127.0.0.1:8000/token completed_in=224.20ms status_code=200
2022-07-14 21:06:53,017 loglevel=INFO   rid=Q0ZXCW request url=http://127.0.0.1:8000/qualityinspection/?filename=dfaljhljadf completed_in=2887.38ms status_code=200
2022-07-14 21:09:54,808 loglevel=INFO   rid=P0NPWU request url=http://127.0.0.1:8000/qualityinspection/ completed_in=0.00ms status_code=405
2022-07-14 21:09:54,840 loglevel=INFO   rid=022DX6 request url=http://127.0.0.1:8000/favicon.ico completed_in=1.00ms status_code=404
2022-07-14 21:13:07,648 loglevel=INFO   Started server process [13036]
2022-07-14 21:13:07,649 loglevel=INFO   Waiting for application startup.
2022-07-14 21:13:07,649 loglevel=INFO   Application startup complete.
2022-07-14 21:13:09,040 loglevel=INFO   rid=FNM5L4 request url=http://127.0.0.1:8000/docs completed_in=0.00ms status_code=200
2022-07-14 21:13:09,110 loglevel=INFO   rid=IIKYY1 request url=http://127.0.0.1:8000/openapi.json completed_in=3.00ms status_code=200
2022-07-14 21:13:16,222 loglevel=ERROR  Exception in ASGI application
Traceback (most recent call last):
  File "H:\Documents\GitHub\Assignment3\venv\lib\site-packages\starlette\middleware\base.py", line 43, in call_next
    message = await recv_stream.receive()
  File "H:\Documents\GitHub\Assignment3\venv\lib\site-packages\anyio\streams\memory.py", line 94, in receive
    return self.receive_nowait()
  File "H:\Documents\GitHub\Assignment3\venv\lib\site-packages\anyio\streams\memory.py", line 87, in receive_nowait
    raise EndOfStream
anyio.EndOfStream

During handling of the above exception, another exception occurred:

Traceback (most recent call last):
  File "H:\Documents\GitHub\Assignment3\venv\lib\site-packages\uvicorn\protocols\http\h11_impl.py", line 403, in run_asgi
    result = await app(self.scope, self.receive, self.send)
  File "H:\Documents\GitHub\Assignment3\venv\lib\site-packages\uvicorn\middleware\proxy_headers.py", line 78, in __call__
    return await self.app(scope, receive, send)
  File "H:\Documents\GitHub\Assignment3\venv\lib\site-packages\fastapi\applications.py", line 269, in __call__
    await super().__call__(scope, receive, send)
  File "H:\Documents\GitHub\Assignment3\venv\lib\site-packages\starlette\applications.py", line 124, in __call__
    await self.middleware_stack(scope, receive, send)
  File "H:\Documents\GitHub\Assignment3\venv\lib\site-packages\starlette\middleware\errors.py", line 184, in __call__
    raise exc
  File "H:\Documents\GitHub\Assignment3\venv\lib\site-packages\starlette\middleware\errors.py", line 162, in __call__
    await self.app(scope, receive, _send)
  File "H:\Documents\GitHub\Assignment3\venv\lib\site-packages\starlette\middleware\base.py", line 68, in __call__
    response = await self.dispatch_func(request, call_next)
  File "H:\Documents\GitHub\Assignment3\src\.\main.py", line 245, in log_requests
    response = await call_next(request)
  File "H:\Documents\GitHub\Assignment3\venv\lib\site-packages\starlette\middleware\base.py", line 46, in call_next
    raise app_exc
  File "H:\Documents\GitHub\Assignment3\venv\lib\site-packages\starlette\middleware\base.py", line 36, in coro
    await self.app(scope, request.receive, send_stream.send)
  File "H:\Documents\GitHub\Assignment3\venv\lib\site-packages\starlette\exceptions.py", line 93, in __call__
    raise exc
  File "H:\Documents\GitHub\Assignment3\venv\lib\site-packages\starlette\exceptions.py", line 82, in __call__
    await self.app(scope, receive, sender)
  File "H:\Documents\GitHub\Assignment3\venv\lib\site-packages\fastapi\middleware\asyncexitstack.py", line 21, in __call__
    raise e
  File "H:\Documents\GitHub\Assignment3\venv\lib\site-packages\fastapi\middleware\asyncexitstack.py", line 18, in __call__
    await self.app(scope, receive, send)
  File "H:\Documents\GitHub\Assignment3\venv\lib\site-packages\starlette\routing.py", line 670, in __call__
    await route.handle(scope, receive, send)
  File "H:\Documents\GitHub\Assignment3\venv\lib\site-packages\starlette\routing.py", line 266, in handle
    await self.app(scope, receive, send)
  File "H:\Documents\GitHub\Assignment3\venv\lib\site-packages\starlette\routing.py", line 65, in app
    response = await func(request)
  File "H:\Documents\GitHub\Assignment3\venv\lib\site-packages\fastapi\routing.py", line 227, in app
    raw_response = await run_endpoint_function(
  File "H:\Documents\GitHub\Assignment3\venv\lib\site-packages\fastapi\routing.py", line 160, in run_endpoint_function
    return await dependant.call(**values)
  File "H:\Documents\GitHub\Assignment3\src\.\main.py", line 308, in qualityinspection
    return file.filename
AttributeError: 'bytes' object has no attribute 'filename'
2022-07-14 21:13:35,246 loglevel=INFO   Started server process [10680]
2022-07-14 21:13:35,247 loglevel=INFO   Waiting for application startup.
2022-07-14 21:13:35,248 loglevel=INFO   Application startup complete.
2022-07-14 21:17:15,118 loglevel=INFO   Started server process [5908]
2022-07-14 21:17:15,119 loglevel=INFO   Waiting for application startup.
2022-07-14 21:17:15,120 loglevel=INFO   Application startup complete.
2022-07-14 21:17:16,279 loglevel=INFO   rid=SDGKFL request url=http://127.0.0.1:8000/docs completed_in=0.00ms status_code=200
2022-07-14 21:17:16,400 loglevel=INFO   rid=T8IBAG request url=http://127.0.0.1:8000/openapi.json completed_in=4.00ms status_code=200
2022-07-14 21:20:44,355 loglevel=INFO   Started server process [3064]
2022-07-14 21:20:44,356 loglevel=INFO   Waiting for application startup.
2022-07-14 21:20:44,356 loglevel=INFO   Application startup complete.
2022-07-14 21:20:49,096 loglevel=INFO   rid=P6BVQ0 request url=http://127.0.0.1:8000/docs completed_in=0.00ms status_code=200
2022-07-14 21:20:49,218 loglevel=INFO   rid=WA3A2H request url=http://127.0.0.1:8000/openapi.json completed_in=5.00ms status_code=200
2022-07-14 21:21:12,154 loglevel=INFO   Started server process [1656]
2022-07-14 21:21:12,155 loglevel=INFO   Waiting for application startup.
2022-07-14 21:21:12,155 loglevel=INFO   Application startup complete.
2022-07-14 21:21:13,179 loglevel=INFO   rid=S39CO6 request url=http://127.0.0.1:8000/docs completed_in=0.00ms status_code=200
2022-07-14 21:21:13,317 loglevel=INFO   rid=T66Z66 request url=http://127.0.0.1:8000/openapi.json completed_in=4.00ms status_code=200
2022-07-14 21:22:39,515 loglevel=INFO   Started server process [15428]
2022-07-14 21:22:39,516 loglevel=INFO   Waiting for application startup.
2022-07-14 21:22:39,516 loglevel=INFO   Application startup complete.

2022-07-11 22:31:35,766 loglevel=INFO   Started server process [2256]
2022-07-11 22:31:35,767 loglevel=INFO   Waiting for application startup.
2022-07-11 22:31:35,767 loglevel=INFO   Application startup complete.
2022-07-11 22:31:36,006 loglevel=INFO   rid=YGOYAA request url=http://127.0.0.1:8000/docs completed_in=0.00ms status_code=200
2022-07-11 22:31:36,331 loglevel=INFO   rid=GZOND9 request url=http://127.0.0.1:8000/openapi.json completed_in=5.01ms status_code=200
2022-07-12 00:02:12,560 loglevel=INFO   Shutting down
2022-07-14 20:22:57,564 loglevel=INFO   Started server process [23684]
2022-07-14 20:22:57,565 loglevel=INFO   Waiting for application startup.
2022-07-14 20:22:57,567 loglevel=INFO   Application startup complete.
2022-07-14 20:23:07,111 loglevel=INFO   rid=Z6QQBM request url=http://127.0.0.1:8000/token completed_in=251.50ms status_code=200
2022-07-14 20:24:55,167 loglevel=INFO   Started server process [16520]
2022-07-14 20:24:55,168 loglevel=INFO   Waiting for application startup.
2022-07-14 20:24:55,168 loglevel=INFO   Application startup complete.

2022-07-14 21:58:03,623 loglevel=INFO   Started server process [13912]
2022-07-14 21:58:03,624 loglevel=INFO   Waiting for application startup.
2022-07-14 21:58:03,624 loglevel=INFO   Application startup complete.
2022-07-14 22:00:04,192 loglevel=INFO   rid=CE21U7 request url=http://127.0.0.1:8000/token completed_in=226.21ms status_code=200
2022-07-14 22:00:12,466 loglevel=INFO   rid=E8M684 request url=http://127.0.0.1:8000/qualityinspection/ completed_in=1.00ms status_code=422
2022-07-14 22:00:43,107 loglevel=INFO   rid=Y6S7JN request url=http://127.0.0.1:8000/token completed_in=204.19ms status_code=200
2022-07-14 22:00:51,107 loglevel=INFO   rid=2CPFYD request url=http://127.0.0.1:8000/token completed_in=205.19ms status_code=200
2022-07-14 22:02:59,850 loglevel=INFO   Started server process [10420]
2022-07-14 22:02:59,851 loglevel=INFO   Waiting for application startup.
2022-07-14 22:02:59,852 loglevel=INFO   Application startup complete.
2022-07-14 22:03:07,427 loglevel=INFO   rid=ALYLVL request url=http://127.0.0.1:8000/token completed_in=225.20ms status_code=200
2022-07-14 22:03:15,898 loglevel=INFO   rid=7G6SHT request url=http://127.0.0.1:8000/token completed_in=205.19ms status_code=200
2022-07-14 22:03:20,447 loglevel=INFO   rid=4OBRK4 request url=http://127.0.0.1:8000/qualityinspection/ completed_in=0.00ms status_code=422
2022-07-14 22:03:57,989 loglevel=INFO   Started server process [7528]
2022-07-14 22:03:57,990 loglevel=INFO   Waiting for application startup.
2022-07-14 22:03:57,990 loglevel=INFO   Application startup complete.
2022-07-14 22:04:27,221 loglevel=INFO   Started server process [1588]
2022-07-14 22:04:27,222 loglevel=INFO   Waiting for application startup.
2022-07-14 22:04:27,222 loglevel=INFO   Application startup complete.
2022-07-14 22:04:32,942 loglevel=INFO   Started server process [11180]
2022-07-14 22:04:32,943 loglevel=INFO   Waiting for application startup.
2022-07-14 22:04:32,943 loglevel=INFO   Application startup complete.
2022-07-14 22:04:36,292 loglevel=INFO   Started server process [7300]
2022-07-14 22:04:36,292 loglevel=INFO   Waiting for application startup.
2022-07-14 22:04:36,293 loglevel=INFO   Application startup complete.
2022-07-14 22:04:43,334 loglevel=INFO   rid=HL1TG6 request url=http://127.0.0.1:8000/token completed_in=226.21ms status_code=200
2022-07-14 22:04:50,586 loglevel=ERROR  Exception in ASGI application
Traceback (most recent call last):
  File "H:\Documents\GitHub\Assignment3\.venv\lib\site-packages\starlette\middleware\base.py", line 43, in call_next
    message = await recv_stream.receive()
  File "H:\Documents\GitHub\Assignment3\.venv\lib\site-packages\anyio\streams\memory.py", line 94, in receive
    return self.receive_nowait()
  File "H:\Documents\GitHub\Assignment3\.venv\lib\site-packages\anyio\streams\memory.py", line 87, in receive_nowait
    raise EndOfStream
anyio.EndOfStream

During handling of the above exception, another exception occurred:

Traceback (most recent call last):
  File "H:\Documents\GitHub\Assignment3\.venv\lib\site-packages\uvicorn\protocols\http\httptools_impl.py", line 372, in run_asgi
    result = await app(self.scope, self.receive, self.send)
  File "H:\Documents\GitHub\Assignment3\.venv\lib\site-packages\uvicorn\middleware\proxy_headers.py", line 75, in __call__
    return await self.app(scope, receive, send)
  File "H:\Documents\GitHub\Assignment3\.venv\lib\site-packages\fastapi\applications.py", line 269, in __call__
    await super().__call__(scope, receive, send)
  File "H:\Documents\GitHub\Assignment3\.venv\lib\site-packages\starlette\applications.py", line 124, in __call__
    await self.middleware_stack(scope, receive, send)
  File "H:\Documents\GitHub\Assignment3\.venv\lib\site-packages\starlette\middleware\errors.py", line 184, in __call__
    raise exc
  File "H:\Documents\GitHub\Assignment3\.venv\lib\site-packages\starlette\middleware\errors.py", line 162, in __call__
    await self.app(scope, receive, _send)
  File "H:\Documents\GitHub\Assignment3\.venv\lib\site-packages\starlette\middleware\base.py", line 68, in __call__
    response = await self.dispatch_func(request, call_next)
  File "H:\Documents\GitHub\Assignment3\src\.\main.py", line 245, in log_requests
    response = await call_next(request)
  File "H:\Documents\GitHub\Assignment3\.venv\lib\site-packages\starlette\middleware\base.py", line 46, in call_next
    raise app_exc
  File "H:\Documents\GitHub\Assignment3\.venv\lib\site-packages\starlette\middleware\base.py", line 36, in coro
    await self.app(scope, request.receive, send_stream.send)
  File "H:\Documents\GitHub\Assignment3\.venv\lib\site-packages\starlette\exceptions.py", line 93, in __call__
    raise exc
  File "H:\Documents\GitHub\Assignment3\.venv\lib\site-packages\starlette\exceptions.py", line 82, in __call__
    await self.app(scope, receive, sender)
  File "H:\Documents\GitHub\Assignment3\.venv\lib\site-packages\fastapi\middleware\asyncexitstack.py", line 21, in __call__
    raise e
  File "H:\Documents\GitHub\Assignment3\.venv\lib\site-packages\fastapi\middleware\asyncexitstack.py", line 18, in __call__
    await self.app(scope, receive, send)
  File "H:\Documents\GitHub\Assignment3\.venv\lib\site-packages\starlette\routing.py", line 670, in __call__
    await route.handle(scope, receive, send)
  File "H:\Documents\GitHub\Assignment3\.venv\lib\site-packages\starlette\routing.py", line 266, in handle
    await self.app(scope, receive, send)
  File "H:\Documents\GitHub\Assignment3\.venv\lib\site-packages\starlette\routing.py", line 65, in app
    response = await func(request)
  File "H:\Documents\GitHub\Assignment3\.venv\lib\site-packages\fastapi\routing.py", line 227, in app
    raw_response = await run_endpoint_function(
  File "H:\Documents\GitHub\Assignment3\.venv\lib\site-packages\fastapi\routing.py", line 160, in run_endpoint_function
    return await dependant.call(**values)
  File "H:\Documents\GitHub\Assignment3\src\.\main.py", line 304, in qualityinspection
    response = test_model.qualityinspection(file)
  File "H:\Documents\GitHub\Assignment3\src\api_functions\test_model.py", line 24, in qualityinspection
    img = Image.open(io.BytesIO(file))
  File "H:\Documents\GitHub\Assignment3\.venv\lib\site-packages\PIL\Image.py", line 3123, in open
    raise UnidentifiedImageError(
PIL.UnidentifiedImageError: cannot identify image file <_io.BytesIO object at 0x0000027F6015DA80>
2022-07-14 22:06:02,443 loglevel=INFO   Started server process [6588]
2022-07-14 22:06:02,444 loglevel=INFO   Waiting for application startup.
2022-07-14 22:06:02,445 loglevel=INFO   Application startup complete.
2022-07-14 22:06:13,811 loglevel=ERROR  Exception in ASGI application
Traceback (most recent call last):
  File "H:\Documents\GitHub\Assignment3\.venv\lib\site-packages\starlette\middleware\base.py", line 43, in call_next
    message = await recv_stream.receive()
  File "H:\Documents\GitHub\Assignment3\.venv\lib\site-packages\anyio\streams\memory.py", line 94, in receive
    return self.receive_nowait()
  File "H:\Documents\GitHub\Assignment3\.venv\lib\site-packages\anyio\streams\memory.py", line 87, in receive_nowait
    raise EndOfStream
anyio.EndOfStream

During handling of the above exception, another exception occurred:

Traceback (most recent call last):
  File "H:\Documents\GitHub\Assignment3\.venv\lib\site-packages\uvicorn\protocols\http\httptools_impl.py", line 372, in run_asgi
    result = await app(self.scope, self.receive, self.send)
  File "H:\Documents\GitHub\Assignment3\.venv\lib\site-packages\uvicorn\middleware\proxy_headers.py", line 75, in __call__
    return await self.app(scope, receive, send)
  File "H:\Documents\GitHub\Assignment3\.venv\lib\site-packages\fastapi\applications.py", line 269, in __call__
    await super().__call__(scope, receive, send)
  File "H:\Documents\GitHub\Assignment3\.venv\lib\site-packages\starlette\applications.py", line 124, in __call__
    await self.middleware_stack(scope, receive, send)
  File "H:\Documents\GitHub\Assignment3\.venv\lib\site-packages\starlette\middleware\errors.py", line 184, in __call__
    raise exc
  File "H:\Documents\GitHub\Assignment3\.venv\lib\site-packages\starlette\middleware\errors.py", line 162, in __call__
    await self.app(scope, receive, _send)
  File "H:\Documents\GitHub\Assignment3\.venv\lib\site-packages\starlette\middleware\base.py", line 68, in __call__
    response = await self.dispatch_func(request, call_next)
  File "H:\Documents\GitHub\Assignment3\src\.\main.py", line 245, in log_requests
    response = await call_next(request)
  File "H:\Documents\GitHub\Assignment3\.venv\lib\site-packages\starlette\middleware\base.py", line 46, in call_next
    raise app_exc
  File "H:\Documents\GitHub\Assignment3\.venv\lib\site-packages\starlette\middleware\base.py", line 36, in coro
    await self.app(scope, request.receive, send_stream.send)
  File "H:\Documents\GitHub\Assignment3\.venv\lib\site-packages\starlette\exceptions.py", line 93, in __call__
    raise exc
  File "H:\Documents\GitHub\Assignment3\.venv\lib\site-packages\starlette\exceptions.py", line 82, in __call__
    await self.app(scope, receive, sender)
  File "H:\Documents\GitHub\Assignment3\.venv\lib\site-packages\fastapi\middleware\asyncexitstack.py", line 21, in __call__
    raise e
  File "H:\Documents\GitHub\Assignment3\.venv\lib\site-packages\fastapi\middleware\asyncexitstack.py", line 18, in __call__
    await self.app(scope, receive, send)
  File "H:\Documents\GitHub\Assignment3\.venv\lib\site-packages\starlette\routing.py", line 670, in __call__
    await route.handle(scope, receive, send)
  File "H:\Documents\GitHub\Assignment3\.venv\lib\site-packages\starlette\routing.py", line 266, in handle
    await self.app(scope, receive, send)
  File "H:\Documents\GitHub\Assignment3\.venv\lib\site-packages\starlette\routing.py", line 65, in app
    response = await func(request)
  File "H:\Documents\GitHub\Assignment3\.venv\lib\site-packages\fastapi\routing.py", line 227, in app
    raw_response = await run_endpoint_function(
  File "H:\Documents\GitHub\Assignment3\.venv\lib\site-packages\fastapi\routing.py", line 160, in run_endpoint_function
    return await dependant.call(**values)
  File "H:\Documents\GitHub\Assignment3\src\.\main.py", line 305, in qualityinspection
    response = test_model.qualityinspection(file)
  File "H:\Documents\GitHub\Assignment3\src\api_functions\test_model.py", line 24, in qualityinspection
    img = Image.open(io.BytesIO(file))
  File "H:\Documents\GitHub\Assignment3\.venv\lib\site-packages\PIL\Image.py", line 3123, in open
    raise UnidentifiedImageError(
PIL.UnidentifiedImageError: cannot identify image file <_io.BytesIO object at 0x0000018D70948860>
2022-07-14 22:06:18,129 loglevel=INFO   rid=8ZKJI0 request url=http://127.0.0.1:8000/docs completed_in=0.00ms status_code=200
2022-07-14 22:06:18,250 loglevel=INFO   rid=D1DMLR request url=http://127.0.0.1:8000/openapi.json completed_in=4.00ms status_code=200
2022-07-14 22:06:27,489 loglevel=INFO   rid=3TC372 request url=http://127.0.0.1:8000/qualityinspection/ completed_in=2983.71ms status_code=200
2022-07-14 22:07:31,239 loglevel=ERROR  Exception in ASGI application
Traceback (most recent call last):
  File "H:\Documents\GitHub\Assignment3\.venv\lib\site-packages\starlette\middleware\base.py", line 43, in call_next
    message = await recv_stream.receive()
  File "H:\Documents\GitHub\Assignment3\.venv\lib\site-packages\anyio\streams\memory.py", line 94, in receive
    return self.receive_nowait()
  File "H:\Documents\GitHub\Assignment3\.venv\lib\site-packages\anyio\streams\memory.py", line 87, in receive_nowait
    raise EndOfStream
anyio.EndOfStream

During handling of the above exception, another exception occurred:

Traceback (most recent call last):
  File "H:\Documents\GitHub\Assignment3\.venv\lib\site-packages\uvicorn\protocols\http\httptools_impl.py", line 372, in run_asgi
    result = await app(self.scope, self.receive, self.send)
  File "H:\Documents\GitHub\Assignment3\.venv\lib\site-packages\uvicorn\middleware\proxy_headers.py", line 75, in __call__
    return await self.app(scope, receive, send)
  File "H:\Documents\GitHub\Assignment3\.venv\lib\site-packages\fastapi\applications.py", line 269, in __call__
    await super().__call__(scope, receive, send)
  File "H:\Documents\GitHub\Assignment3\.venv\lib\site-packages\starlette\applications.py", line 124, in __call__
    await self.middleware_stack(scope, receive, send)
  File "H:\Documents\GitHub\Assignment3\.venv\lib\site-packages\starlette\middleware\errors.py", line 184, in __call__
    raise exc
  File "H:\Documents\GitHub\Assignment3\.venv\lib\site-packages\starlette\middleware\errors.py", line 162, in __call__
    await self.app(scope, receive, _send)
  File "H:\Documents\GitHub\Assignment3\.venv\lib\site-packages\starlette\middleware\base.py", line 68, in __call__
    response = await self.dispatch_func(request, call_next)
  File "H:\Documents\GitHub\Assignment3\src\.\main.py", line 245, in log_requests
    response = await call_next(request)
  File "H:\Documents\GitHub\Assignment3\.venv\lib\site-packages\starlette\middleware\base.py", line 46, in call_next
    raise app_exc
  File "H:\Documents\GitHub\Assignment3\.venv\lib\site-packages\starlette\middleware\base.py", line 36, in coro
    await self.app(scope, request.receive, send_stream.send)
  File "H:\Documents\GitHub\Assignment3\.venv\lib\site-packages\starlette\exceptions.py", line 93, in __call__
    raise exc
  File "H:\Documents\GitHub\Assignment3\.venv\lib\site-packages\starlette\exceptions.py", line 82, in __call__
    await self.app(scope, receive, sender)
  File "H:\Documents\GitHub\Assignment3\.venv\lib\site-packages\fastapi\middleware\asyncexitstack.py", line 21, in __call__
    raise e
  File "H:\Documents\GitHub\Assignment3\.venv\lib\site-packages\fastapi\middleware\asyncexitstack.py", line 18, in __call__
    await self.app(scope, receive, send)
  File "H:\Documents\GitHub\Assignment3\.venv\lib\site-packages\starlette\routing.py", line 670, in __call__
    await route.handle(scope, receive, send)
  File "H:\Documents\GitHub\Assignment3\.venv\lib\site-packages\starlette\routing.py", line 266, in handle
    await self.app(scope, receive, send)
  File "H:\Documents\GitHub\Assignment3\.venv\lib\site-packages\starlette\routing.py", line 65, in app
    response = await func(request)
  File "H:\Documents\GitHub\Assignment3\.venv\lib\site-packages\fastapi\routing.py", line 227, in app
    raw_response = await run_endpoint_function(
  File "H:\Documents\GitHub\Assignment3\.venv\lib\site-packages\fastapi\routing.py", line 160, in run_endpoint_function
    return await dependant.call(**values)
  File "H:\Documents\GitHub\Assignment3\src\.\main.py", line 305, in qualityinspection
    response = test_model.qualityinspection(file)
  File "H:\Documents\GitHub\Assignment3\src\api_functions\test_model.py", line 24, in qualityinspection
    img = Image.open(io.BytesIO(file))
  File "H:\Documents\GitHub\Assignment3\.venv\lib\site-packages\PIL\Image.py", line 3123, in open
    raise UnidentifiedImageError(
PIL.UnidentifiedImageError: cannot identify image file <_io.BytesIO object at 0x0000018D70232980>
2022-07-14 22:17:06,721 loglevel=INFO   Started server process [15992]
2022-07-14 22:17:06,722 loglevel=INFO   Waiting for application startup.
2022-07-14 22:17:06,722 loglevel=INFO   Application startup complete.
2022-07-14 22:19:31,543 loglevel=INFO   rid=CDRJF6 request url=http://127.0.0.1:8000/docs completed_in=0.00ms status_code=200
2022-07-14 22:19:31,664 loglevel=INFO   rid=QK3P03 request url=http://127.0.0.1:8000/openapi.json completed_in=4.00ms status_code=200
2022-07-14 22:19:50,046 loglevel=INFO   Started server process [15704]
2022-07-14 22:19:50,047 loglevel=INFO   Waiting for application startup.
2022-07-14 22:19:50,047 loglevel=INFO   Application startup complete.
2022-07-14 22:19:51,805 loglevel=INFO   rid=KUH7FF request url=http://127.0.0.1:8000/docs completed_in=0.00ms status_code=200
2022-07-14 22:19:51,927 loglevel=INFO   rid=RRKD63 request url=http://127.0.0.1:8000/openapi.json completed_in=4.00ms status_code=200
2022-07-14 22:20:00,584 loglevel=INFO   rid=NGJQB7 request url=http://127.0.0.1:8000/qualityinspection/ completed_in=2966.87ms status_code=200
2022-07-14 22:29:48,583 loglevel=INFO   Started server process [6468]
2022-07-14 22:29:48,584 loglevel=INFO   Waiting for application startup.
2022-07-14 22:29:48,584 loglevel=INFO   Application startup complete.
2022-07-14 22:33:08,755 loglevel=INFO   Started server process [9792]
2022-07-14 22:33:08,756 loglevel=INFO   Waiting for application startup.
2022-07-14 22:33:08,756 loglevel=INFO   Application startup complete.
2022-07-14 22:33:09,469 loglevel=INFO   rid=VTG1MS request url=http://127.0.0.1:8000/qualityinspection/ completed_in=1.00ms status_code=400
2022-07-14 22:33:09,517 loglevel=INFO   rid=5FL07W request url=http://127.0.0.1:8000/qualityinspection/ completed_in=1.00ms status_code=400
2022-07-14 22:33:13,541 loglevel=INFO   rid=SLZ3W3 request url=http://127.0.0.1:8000/qualityinspection/ completed_in=0.00ms status_code=400
2022-07-14 22:33:13,545 loglevel=INFO   rid=V35V34 request url=http://127.0.0.1:8000/qualityinspection/ completed_in=0.00ms status_code=400
2022-07-14 22:33:19,354 loglevel=INFO   rid=BQOXAJ request url=http://127.0.0.1:8000/qualityinspection/ completed_in=1.00ms status_code=400
2022-07-14 22:33:48,036 loglevel=INFO   Started server process [16628]
2022-07-14 22:33:48,036 loglevel=INFO   Waiting for application startup.
2022-07-14 22:33:48,037 loglevel=INFO   Application startup complete.
2022-07-14 22:33:51,170 loglevel=INFO   rid=D21KUY request url=http://127.0.0.1:8000/qualityinspection/ completed_in=0.00ms status_code=400
2022-07-14 22:33:56,550 loglevel=INFO   rid=B6NV16 request url=http://127.0.0.1:8000/qualityinspection/ completed_in=1.00ms status_code=400
2022-07-14 22:34:44,549 loglevel=INFO   Started server process [8208]
2022-07-14 22:34:44,550 loglevel=INFO   Waiting for application startup.
2022-07-14 22:34:44,550 loglevel=INFO   Application startup complete.
2022-07-14 22:34:46,696 loglevel=INFO   rid=YW02XU request url=http://127.0.0.1:8000/qualityinspection/ completed_in=0.00ms status_code=400
2022-07-14 22:34:48,800 loglevel=INFO   rid=C0J5QH request url=http://127.0.0.1:8000/qualityinspection/ completed_in=0.00ms status_code=400
2022-07-14 22:34:52,020 loglevel=INFO   rid=22UVVI request url=http://127.0.0.1:8000/qualityinspection/ completed_in=0.00ms status_code=400
2022-07-14 22:38:59,633 loglevel=INFO   Started server process [6916]
2022-07-14 22:38:59,634 loglevel=INFO   Waiting for application startup.
2022-07-14 22:38:59,634 loglevel=INFO   Application startup complete.
2022-07-14 22:39:54,089 loglevel=INFO   Started server process [17328]
2022-07-14 22:39:54,090 loglevel=INFO   Waiting for application startup.
2022-07-14 22:39:54,091 loglevel=INFO   Application startup complete.
2022-07-14 22:40:39,964 loglevel=INFO   Started server process [9072]
2022-07-14 22:40:39,964 loglevel=INFO   Waiting for application startup.
2022-07-14 22:40:39,965 loglevel=INFO   Application startup complete.
2022-07-14 22:41:39,063 loglevel=INFO   Started server process [16500]
2022-07-14 22:41:39,064 loglevel=INFO   Waiting for application startup.
2022-07-14 22:41:39,065 loglevel=INFO   Application startup complete.
2022-07-14 22:45:11,203 loglevel=INFO   rid=UZGNHV request url=http://127.0.0.1:8000/qualityinspection/ completed_in=2997.35ms status_code=200
2022-07-14 22:46:49,738 loglevel=INFO   Started server process [284]
2022-07-14 22:46:49,739 loglevel=INFO   Waiting for application startup.
2022-07-14 22:46:49,739 loglevel=INFO   Application startup complete.
2022-07-14 22:48:05,704 loglevel=INFO   Started server process [17276]
2022-07-14 22:48:05,704 loglevel=INFO   Waiting for application startup.
2022-07-14 22:48:05,705 loglevel=INFO   Application startup complete.
2022-07-14 22:50:13,160 loglevel=INFO   Started server process [3688]
2022-07-14 22:50:13,161 loglevel=INFO   Waiting for application startup.
2022-07-14 22:50:13,161 loglevel=INFO   Application startup complete.
2022-07-14 22:50:20,855 loglevel=ERROR  Exception in ASGI application
Traceback (most recent call last):
  File "H:\Documents\GitHub\Assignment3\.venv\lib\site-packages\starlette\middleware\base.py", line 43, in call_next
    message = await recv_stream.receive()
  File "H:\Documents\GitHub\Assignment3\.venv\lib\site-packages\anyio\streams\memory.py", line 94, in receive
    return self.receive_nowait()
  File "H:\Documents\GitHub\Assignment3\.venv\lib\site-packages\anyio\streams\memory.py", line 87, in receive_nowait
    raise EndOfStream
anyio.EndOfStream

During handling of the above exception, another exception occurred:

Traceback (most recent call last):
  File "H:\Documents\GitHub\Assignment3\.venv\lib\site-packages\uvicorn\protocols\http\httptools_impl.py", line 372, in run_asgi
    result = await app(self.scope, self.receive, self.send)
  File "H:\Documents\GitHub\Assignment3\.venv\lib\site-packages\uvicorn\middleware\proxy_headers.py", line 75, in __call__
    return await self.app(scope, receive, send)
  File "H:\Documents\GitHub\Assignment3\.venv\lib\site-packages\fastapi\applications.py", line 269, in __call__
    await super().__call__(scope, receive, send)
  File "H:\Documents\GitHub\Assignment3\.venv\lib\site-packages\starlette\applications.py", line 124, in __call__
    await self.middleware_stack(scope, receive, send)
  File "H:\Documents\GitHub\Assignment3\.venv\lib\site-packages\starlette\middleware\errors.py", line 184, in __call__
    raise exc
  File "H:\Documents\GitHub\Assignment3\.venv\lib\site-packages\starlette\middleware\errors.py", line 162, in __call__
    await self.app(scope, receive, _send)
  File "H:\Documents\GitHub\Assignment3\.venv\lib\site-packages\starlette\middleware\base.py", line 68, in __call__
    response = await self.dispatch_func(request, call_next)
  File "H:\Documents\GitHub\Assignment3\src\.\main.py", line 245, in log_requests
    response = await call_next(request)
  File "H:\Documents\GitHub\Assignment3\.venv\lib\site-packages\starlette\middleware\base.py", line 46, in call_next
    raise app_exc
  File "H:\Documents\GitHub\Assignment3\.venv\lib\site-packages\starlette\middleware\base.py", line 36, in coro
    await self.app(scope, request.receive, send_stream.send)
  File "H:\Documents\GitHub\Assignment3\.venv\lib\site-packages\starlette\exceptions.py", line 93, in __call__
    raise exc
  File "H:\Documents\GitHub\Assignment3\.venv\lib\site-packages\starlette\exceptions.py", line 82, in __call__
    await self.app(scope, receive, sender)
  File "H:\Documents\GitHub\Assignment3\.venv\lib\site-packages\fastapi\middleware\asyncexitstack.py", line 21, in __call__
    raise e
  File "H:\Documents\GitHub\Assignment3\.venv\lib\site-packages\fastapi\middleware\asyncexitstack.py", line 18, in __call__
    await self.app(scope, receive, send)
  File "H:\Documents\GitHub\Assignment3\.venv\lib\site-packages\starlette\routing.py", line 670, in __call__
    await route.handle(scope, receive, send)
  File "H:\Documents\GitHub\Assignment3\.venv\lib\site-packages\starlette\routing.py", line 266, in handle
    await self.app(scope, receive, send)
  File "H:\Documents\GitHub\Assignment3\.venv\lib\site-packages\starlette\routing.py", line 65, in app
    response = await func(request)
  File "H:\Documents\GitHub\Assignment3\.venv\lib\site-packages\fastapi\routing.py", line 227, in app
    raw_response = await run_endpoint_function(
  File "H:\Documents\GitHub\Assignment3\.venv\lib\site-packages\fastapi\routing.py", line 160, in run_endpoint_function
    return await dependant.call(**values)
  File "H:\Documents\GitHub\Assignment3\src\.\main.py", line 305, in qualityinspection
    response = test_model.qualityinspection(file)
  File "H:\Documents\GitHub\Assignment3\src\api_functions\test_model.py", line 24, in qualityinspection
    img = Image.open(io.BytesIO(file))
  File "H:\Documents\GitHub\Assignment3\.venv\lib\site-packages\PIL\Image.py", line 3123, in open
    raise UnidentifiedImageError(
PIL.UnidentifiedImageError: cannot identify image file <_io.BytesIO object at 0x000002216FF7E930>
2022-07-14 23:05:38,214 loglevel=INFO   Started server process [8176]
2022-07-14 23:05:38,215 loglevel=INFO   Waiting for application startup.
2022-07-14 23:05:38,215 loglevel=INFO   Application startup complete.
2022-07-14 23:05:45,739 loglevel=INFO   rid=C1RINI request url=http://127.0.0.1:8000/qualityinspection/ completed_in=2975.89ms status_code=200
2022-07-14 23:08:18,934 loglevel=INFO   Started server process [11448]
2022-07-14 23:08:18,935 loglevel=INFO   Waiting for application startup.
2022-07-14 23:08:18,936 loglevel=INFO   Application startup complete.
2022-07-14 23:08:26,575 loglevel=INFO   rid=4MY18T request url=http://127.0.0.1:8000/qualityinspection/ completed_in=2926.66ms status_code=200
2022-07-14 23:10:36,752 loglevel=INFO   Started server process [11508]
2022-07-14 23:10:36,752 loglevel=INFO   Waiting for application startup.
2022-07-14 23:10:36,753 loglevel=INFO   Application startup complete.
2022-07-14 23:10:47,948 loglevel=INFO   rid=CUFBV7 request url=http://127.0.0.1:8000/qualityinspection/ completed_in=2917.14ms status_code=200
2022-07-14 23:12:30,177 loglevel=INFO   Started server process [8460]
2022-07-14 23:12:30,177 loglevel=INFO   Waiting for application startup.
2022-07-14 23:12:30,178 loglevel=INFO   Application startup complete.
2022-07-14 23:12:37,535 loglevel=INFO   rid=KP1DL0 request url=http://127.0.0.1:8000/qualityinspection/ completed_in=2946.63ms status_code=200
2022-07-14 23:13:16,555 loglevel=INFO   Started server process [3820]
2022-07-14 23:13:16,555 loglevel=INFO   Waiting for application startup.
2022-07-14 23:13:16,556 loglevel=INFO   Application startup complete.
2022-07-14 23:13:17,100 loglevel=INFO   Shutting down
2022-07-14 23:13:17,210 loglevel=INFO   Waiting for application shutdown.
2022-07-14 23:13:17,210 loglevel=INFO   Application shutdown complete.
2022-07-14 23:13:17,211 loglevel=INFO   Finished server process [3820]
2022-07-15 01:26:59,774 loglevel=INFO   Started server process [6620]
2022-07-15 01:26:59,775 loglevel=INFO   Waiting for application startup.
2022-07-15 01:26:59,776 loglevel=INFO   Application startup complete.
2022-07-15 01:26:59,884 loglevel=INFO   rid=IQK70T request url=http://127.0.0.1:8000/ completed_in=0.00ms status_code=200
2022-07-15 01:26:59,960 loglevel=INFO   rid=HJ8SCC request url=http://127.0.0.1:8000/static/0041e69431bf872309d1aff628b6494f.jpg completed_in=48.04ms status_code=200
2022-07-15 01:27:00,867 loglevel=INFO   rid=7KXFCU request url=http://127.0.0.1:8000/docs completed_in=0.00ms status_code=200
2022-07-15 01:27:01,105 loglevel=INFO   rid=3G7OLE request url=http://127.0.0.1:8000/openapi.json completed_in=3.00ms status_code=200
2022-07-15 01:27:11,243 loglevel=ERROR  Exception in ASGI application
Traceback (most recent call last):
  File "H:\Documents\GitHub\Assignment3\.venv\lib\site-packages\starlette\middleware\base.py", line 43, in call_next
    message = await recv_stream.receive()
  File "H:\Documents\GitHub\Assignment3\.venv\lib\site-packages\anyio\streams\memory.py", line 94, in receive
    return self.receive_nowait()
  File "H:\Documents\GitHub\Assignment3\.venv\lib\site-packages\anyio\streams\memory.py", line 87, in receive_nowait
    raise EndOfStream
anyio.EndOfStream

During handling of the above exception, another exception occurred:

Traceback (most recent call last):
  File "H:\Documents\GitHub\Assignment3\.venv\lib\site-packages\uvicorn\protocols\http\httptools_impl.py", line 372, in run_asgi
    result = await app(self.scope, self.receive, self.send)
  File "H:\Documents\GitHub\Assignment3\.venv\lib\site-packages\uvicorn\middleware\proxy_headers.py", line 75, in __call__
    return await self.app(scope, receive, send)
  File "H:\Documents\GitHub\Assignment3\.venv\lib\site-packages\fastapi\applications.py", line 269, in __call__
    await super().__call__(scope, receive, send)
  File "H:\Documents\GitHub\Assignment3\.venv\lib\site-packages\starlette\applications.py", line 124, in __call__
    await self.middleware_stack(scope, receive, send)
  File "H:\Documents\GitHub\Assignment3\.venv\lib\site-packages\starlette\middleware\errors.py", line 184, in __call__
    raise exc
  File "H:\Documents\GitHub\Assignment3\.venv\lib\site-packages\starlette\middleware\errors.py", line 162, in __call__
    await self.app(scope, receive, _send)
  File "H:\Documents\GitHub\Assignment3\.venv\lib\site-packages\starlette\middleware\base.py", line 68, in __call__
    response = await self.dispatch_func(request, call_next)
  File "H:\Documents\GitHub\Assignment3\src\.\main.py", line 245, in log_requests
    response = await call_next(request)
  File "H:\Documents\GitHub\Assignment3\.venv\lib\site-packages\starlette\middleware\base.py", line 46, in call_next
    raise app_exc
  File "H:\Documents\GitHub\Assignment3\.venv\lib\site-packages\starlette\middleware\base.py", line 36, in coro
    await self.app(scope, request.receive, send_stream.send)
  File "H:\Documents\GitHub\Assignment3\.venv\lib\site-packages\starlette\exceptions.py", line 93, in __call__
    raise exc
  File "H:\Documents\GitHub\Assignment3\.venv\lib\site-packages\starlette\exceptions.py", line 82, in __call__
    await self.app(scope, receive, sender)
  File "H:\Documents\GitHub\Assignment3\.venv\lib\site-packages\fastapi\middleware\asyncexitstack.py", line 21, in __call__
    raise e
  File "H:\Documents\GitHub\Assignment3\.venv\lib\site-packages\fastapi\middleware\asyncexitstack.py", line 18, in __call__
    await self.app(scope, receive, send)
  File "H:\Documents\GitHub\Assignment3\.venv\lib\site-packages\starlette\routing.py", line 670, in __call__
    await route.handle(scope, receive, send)
  File "H:\Documents\GitHub\Assignment3\.venv\lib\site-packages\starlette\routing.py", line 266, in handle
    await self.app(scope, receive, send)
  File "H:\Documents\GitHub\Assignment3\.venv\lib\site-packages\starlette\routing.py", line 65, in app
    response = await func(request)
  File "H:\Documents\GitHub\Assignment3\.venv\lib\site-packages\fastapi\routing.py", line 227, in app
    raw_response = await run_endpoint_function(
  File "H:\Documents\GitHub\Assignment3\.venv\lib\site-packages\fastapi\routing.py", line 160, in run_endpoint_function
    return await dependant.call(**values)
  File "H:\Documents\GitHub\Assignment3\src\.\main.py", line 305, in qualityinspection
    response = test_model.qualityinspection(file)
  File "H:\Documents\GitHub\Assignment3\src\api_functions\test_model.py", line 15, in qualityinspection
    model = pickle.load(open(model_path, 'rb'))
FileNotFoundError: [Errno 2] No such file or directory: 'H:\\Documents\\GitHub\\Assignment3\\model_pkl.pkl'
2022-07-15 01:27:50,595 loglevel=INFO   Started server process [15988]
2022-07-15 01:27:50,596 loglevel=INFO   Waiting for application startup.
2022-07-15 01:27:50,596 loglevel=INFO   Application startup complete.
2022-07-15 01:28:01,111 loglevel=ERROR  Exception in ASGI application
Traceback (most recent call last):
  File "H:\Documents\GitHub\Assignment3\.venv\lib\site-packages\uvicorn\protocols\http\httptools_impl.py", line 372, in run_asgi
    result = await app(self.scope, self.receive, self.send)
  File "H:\Documents\GitHub\Assignment3\.venv\lib\site-packages\uvicorn\middleware\proxy_headers.py", line 75, in __call__
    return await self.app(scope, receive, send)
  File "H:\Documents\GitHub\Assignment3\.venv\lib\site-packages\fastapi\applications.py", line 269, in __call__
    await super().__call__(scope, receive, send)
  File "H:\Documents\GitHub\Assignment3\.venv\lib\site-packages\starlette\applications.py", line 124, in __call__
    await self.middleware_stack(scope, receive, send)
  File "H:\Documents\GitHub\Assignment3\.venv\lib\site-packages\starlette\middleware\errors.py", line 184, in __call__
    raise exc
  File "H:\Documents\GitHub\Assignment3\.venv\lib\site-packages\starlette\middleware\errors.py", line 162, in __call__
    await self.app(scope, receive, _send)
  File "H:\Documents\GitHub\Assignment3\.venv\lib\site-packages\starlette\middleware\base.py", line 68, in __call__
    response = await self.dispatch_func(request, call_next)
  File "H:\Documents\GitHub\Assignment3\src\.\main.py", line 245, in log_requests
    response = await call_next(request)
  File "H:\Documents\GitHub\Assignment3\.venv\lib\site-packages\starlette\middleware\base.py", line 46, in call_next
    raise app_exc
  File "H:\Documents\GitHub\Assignment3\.venv\lib\site-packages\starlette\middleware\base.py", line 36, in coro
    await self.app(scope, request.receive, send_stream.send)
  File "H:\Documents\GitHub\Assignment3\.venv\lib\site-packages\starlette\exceptions.py", line 93, in __call__
    raise exc
  File "H:\Documents\GitHub\Assignment3\.venv\lib\site-packages\starlette\exceptions.py", line 82, in __call__
    await self.app(scope, receive, sender)
  File "H:\Documents\GitHub\Assignment3\.venv\lib\site-packages\fastapi\middleware\asyncexitstack.py", line 21, in __call__
    raise e
  File "H:\Documents\GitHub\Assignment3\.venv\lib\site-packages\fastapi\middleware\asyncexitstack.py", line 18, in __call__
    await self.app(scope, receive, send)
  File "H:\Documents\GitHub\Assignment3\.venv\lib\site-packages\starlette\routing.py", line 670, in __call__
    await route.handle(scope, receive, send)
  File "H:\Documents\GitHub\Assignment3\.venv\lib\site-packages\starlette\routing.py", line 266, in handle
    await self.app(scope, receive, send)
  File "H:\Documents\GitHub\Assignment3\.venv\lib\site-packages\starlette\routing.py", line 65, in app
    response = await func(request)
  File "H:\Documents\GitHub\Assignment3\.venv\lib\site-packages\fastapi\routing.py", line 227, in app
    raw_response = await run_endpoint_function(
  File "H:\Documents\GitHub\Assignment3\.venv\lib\site-packages\fastapi\routing.py", line 160, in run_endpoint_function
    return await dependant.call(**values)
  File "H:\Documents\GitHub\Assignment3\src\.\main.py", line 305, in qualityinspection
    response = test_model.qualityinspection(file)
  File "H:\Documents\GitHub\Assignment3\src\api_functions\test_model.py", line 15, in qualityinspection
    model = pickle.load(open(model_path, 'rb'))
  File "H:\Documents\GitHub\Assignment3\.venv\lib\site-packages\keras\saving\pickle_utils.py", line 48, in deserialize_model_from_bytecode
    model = save_module.load_model(temp_dir)
  File "H:\Documents\GitHub\Assignment3\.venv\lib\site-packages\keras\utils\traceback_utils.py", line 67, in error_handler
    raise e.with_traceback(filtered_tb) from None
  File "H:\Documents\GitHub\Assignment3\.venv\lib\site-packages\tensorflow\python\saved_model\load.py", line 915, in load_partial
    raise FileNotFoundError(
FileNotFoundError: Unsuccessful TensorSliceReader constructor: Failed to find any matching files for ram://c56636e5-0fde-4468-870c-6fcfbcc4918f/variables/variables
 You may be trying to load on a different device from the computational device. Consider setting the `experimental_io_device` option in `tf.saved_model.LoadOptions` to the io_device such as '/job:localhost'.
2022-07-15 01:30:32,972 loglevel=INFO   Started server process [1084]
2022-07-15 01:30:32,973 loglevel=INFO   Waiting for application startup.
2022-07-15 01:30:32,973 loglevel=INFO   Application startup complete.
2022-07-15 01:30:36,862 loglevel=INFO   rid=5CG4OO request url=http://127.0.0.1:8000/docs completed_in=0.00ms status_code=200
2022-07-15 01:30:36,990 loglevel=INFO   rid=W11K9T request url=http://127.0.0.1:8000/openapi.json completed_in=3.00ms status_code=200
2022-07-15 01:30:50,594 loglevel=ERROR  Exception in ASGI application
Traceback (most recent call last):
  File "H:\Documents\GitHub\Assignment3\.venv\lib\site-packages\uvicorn\protocols\http\httptools_impl.py", line 372, in run_asgi
    result = await app(self.scope, self.receive, self.send)
  File "H:\Documents\GitHub\Assignment3\.venv\lib\site-packages\uvicorn\middleware\proxy_headers.py", line 75, in __call__
    return await self.app(scope, receive, send)
  File "H:\Documents\GitHub\Assignment3\.venv\lib\site-packages\fastapi\applications.py", line 269, in __call__
    await super().__call__(scope, receive, send)
  File "H:\Documents\GitHub\Assignment3\.venv\lib\site-packages\starlette\applications.py", line 124, in __call__
    await self.middleware_stack(scope, receive, send)
  File "H:\Documents\GitHub\Assignment3\.venv\lib\site-packages\starlette\middleware\errors.py", line 184, in __call__
    raise exc
  File "H:\Documents\GitHub\Assignment3\.venv\lib\site-packages\starlette\middleware\errors.py", line 162, in __call__
    await self.app(scope, receive, _send)
  File "H:\Documents\GitHub\Assignment3\.venv\lib\site-packages\starlette\middleware\base.py", line 68, in __call__
    response = await self.dispatch_func(request, call_next)
  File "H:\Documents\GitHub\Assignment3\src\.\main.py", line 245, in log_requests
    response = await call_next(request)
  File "H:\Documents\GitHub\Assignment3\.venv\lib\site-packages\starlette\middleware\base.py", line 46, in call_next
    raise app_exc
  File "H:\Documents\GitHub\Assignment3\.venv\lib\site-packages\starlette\middleware\base.py", line 36, in coro
    await self.app(scope, request.receive, send_stream.send)
  File "H:\Documents\GitHub\Assignment3\.venv\lib\site-packages\starlette\exceptions.py", line 93, in __call__
    raise exc
  File "H:\Documents\GitHub\Assignment3\.venv\lib\site-packages\starlette\exceptions.py", line 82, in __call__
    await self.app(scope, receive, sender)
  File "H:\Documents\GitHub\Assignment3\.venv\lib\site-packages\fastapi\middleware\asyncexitstack.py", line 21, in __call__
    raise e
  File "H:\Documents\GitHub\Assignment3\.venv\lib\site-packages\fastapi\middleware\asyncexitstack.py", line 18, in __call__
    await self.app(scope, receive, send)
  File "H:\Documents\GitHub\Assignment3\.venv\lib\site-packages\starlette\routing.py", line 670, in __call__
    await route.handle(scope, receive, send)
  File "H:\Documents\GitHub\Assignment3\.venv\lib\site-packages\starlette\routing.py", line 266, in handle
    await self.app(scope, receive, send)
  File "H:\Documents\GitHub\Assignment3\.venv\lib\site-packages\starlette\routing.py", line 65, in app
    response = await func(request)
  File "H:\Documents\GitHub\Assignment3\.venv\lib\site-packages\fastapi\routing.py", line 227, in app
    raw_response = await run_endpoint_function(
  File "H:\Documents\GitHub\Assignment3\.venv\lib\site-packages\fastapi\routing.py", line 160, in run_endpoint_function
    return await dependant.call(**values)
  File "H:\Documents\GitHub\Assignment3\src\.\main.py", line 305, in qualityinspection
    response = test_model.qualityinspection(file)
  File "H:\Documents\GitHub\Assignment3\src\api_functions\test_model.py", line 16, in qualityinspection
    model = pickle.load(file)
  File "H:\Documents\GitHub\Assignment3\.venv\lib\site-packages\keras\saving\pickle_utils.py", line 48, in deserialize_model_from_bytecode
    model = save_module.load_model(temp_dir)
  File "H:\Documents\GitHub\Assignment3\.venv\lib\site-packages\keras\utils\traceback_utils.py", line 67, in error_handler
    raise e.with_traceback(filtered_tb) from None
  File "H:\Documents\GitHub\Assignment3\.venv\lib\site-packages\tensorflow\python\saved_model\load.py", line 915, in load_partial
    raise FileNotFoundError(
FileNotFoundError: Unsuccessful TensorSliceReader constructor: Failed to find any matching files for ram://da16d577-a4b7-42fb-bd41-a9bf1d0dad6f/variables/variables
 You may be trying to load on a different device from the computational device. Consider setting the `experimental_io_device` option in `tf.saved_model.LoadOptions` to the io_device such as '/job:localhost'.
2022-07-15 01:37:09,543 loglevel=INFO   Started server process [4828]
2022-07-15 01:37:09,544 loglevel=INFO   Waiting for application startup.
2022-07-15 01:37:09,544 loglevel=INFO   Application startup complete.
2022-07-15 01:37:11,134 loglevel=ERROR  Exception in ASGI application
Traceback (most recent call last):
  File "H:\Documents\GitHub\Assignment3\.venv\lib\site-packages\starlette\middleware\base.py", line 43, in call_next
    message = await recv_stream.receive()
  File "H:\Documents\GitHub\Assignment3\.venv\lib\site-packages\anyio\streams\memory.py", line 94, in receive
    return self.receive_nowait()
  File "H:\Documents\GitHub\Assignment3\.venv\lib\site-packages\anyio\streams\memory.py", line 87, in receive_nowait
    raise EndOfStream
anyio.EndOfStream

During handling of the above exception, another exception occurred:

Traceback (most recent call last):
  File "H:\Documents\GitHub\Assignment3\.venv\lib\site-packages\uvicorn\protocols\http\httptools_impl.py", line 372, in run_asgi
    result = await app(self.scope, self.receive, self.send)
  File "H:\Documents\GitHub\Assignment3\.venv\lib\site-packages\uvicorn\middleware\proxy_headers.py", line 75, in __call__
    return await self.app(scope, receive, send)
  File "H:\Documents\GitHub\Assignment3\.venv\lib\site-packages\fastapi\applications.py", line 269, in __call__
    await super().__call__(scope, receive, send)
  File "H:\Documents\GitHub\Assignment3\.venv\lib\site-packages\starlette\applications.py", line 124, in __call__
    await self.middleware_stack(scope, receive, send)
  File "H:\Documents\GitHub\Assignment3\.venv\lib\site-packages\starlette\middleware\errors.py", line 184, in __call__
    raise exc
  File "H:\Documents\GitHub\Assignment3\.venv\lib\site-packages\starlette\middleware\errors.py", line 162, in __call__
    await self.app(scope, receive, _send)
  File "H:\Documents\GitHub\Assignment3\.venv\lib\site-packages\starlette\middleware\base.py", line 68, in __call__
    response = await self.dispatch_func(request, call_next)
  File "H:\Documents\GitHub\Assignment3\src\.\main.py", line 245, in log_requests
    response = await call_next(request)
  File "H:\Documents\GitHub\Assignment3\.venv\lib\site-packages\starlette\middleware\base.py", line 46, in call_next
    raise app_exc
  File "H:\Documents\GitHub\Assignment3\.venv\lib\site-packages\starlette\middleware\base.py", line 36, in coro
    await self.app(scope, request.receive, send_stream.send)
  File "H:\Documents\GitHub\Assignment3\.venv\lib\site-packages\starlette\exceptions.py", line 93, in __call__
    raise exc
  File "H:\Documents\GitHub\Assignment3\.venv\lib\site-packages\starlette\exceptions.py", line 82, in __call__
    await self.app(scope, receive, sender)
  File "H:\Documents\GitHub\Assignment3\.venv\lib\site-packages\fastapi\middleware\asyncexitstack.py", line 21, in __call__
    raise e
  File "H:\Documents\GitHub\Assignment3\.venv\lib\site-packages\fastapi\middleware\asyncexitstack.py", line 18, in __call__
    await self.app(scope, receive, send)
  File "H:\Documents\GitHub\Assignment3\.venv\lib\site-packages\starlette\routing.py", line 670, in __call__
    await route.handle(scope, receive, send)
  File "H:\Documents\GitHub\Assignment3\.venv\lib\site-packages\starlette\routing.py", line 266, in handle
    await self.app(scope, receive, send)
  File "H:\Documents\GitHub\Assignment3\.venv\lib\site-packages\starlette\routing.py", line 65, in app
    response = await func(request)
  File "H:\Documents\GitHub\Assignment3\.venv\lib\site-packages\fastapi\routing.py", line 227, in app
    raw_response = await run_endpoint_function(
  File "H:\Documents\GitHub\Assignment3\.venv\lib\site-packages\fastapi\routing.py", line 160, in run_endpoint_function
    return await dependant.call(**values)
  File "H:\Documents\GitHub\Assignment3\src\.\main.py", line 305, in qualityinspection
    response = test_model.qualityinspection(file)
  File "H:\Documents\GitHub\Assignment3\src\api_functions\test_model.py", line 16, in qualityinspection
    with open('model_pkl.pkl', 'rb') as file:
FileNotFoundError: [Errno 2] No such file or directory: 'model_pkl.pkl'
2022-07-15 01:37:37,596 loglevel=INFO   Started server process [18312]
2022-07-15 01:37:37,596 loglevel=INFO   Waiting for application startup.
2022-07-15 01:37:37,597 loglevel=INFO   Application startup complete.
2022-07-15 01:37:38,901 loglevel=ERROR  Exception in ASGI application
Traceback (most recent call last):
  File "H:\Documents\GitHub\Assignment3\.venv\lib\site-packages\starlette\middleware\base.py", line 43, in call_next
    message = await recv_stream.receive()
  File "H:\Documents\GitHub\Assignment3\.venv\lib\site-packages\anyio\streams\memory.py", line 94, in receive
    return self.receive_nowait()
  File "H:\Documents\GitHub\Assignment3\.venv\lib\site-packages\anyio\streams\memory.py", line 87, in receive_nowait
    raise EndOfStream
anyio.EndOfStream

During handling of the above exception, another exception occurred:

Traceback (most recent call last):
  File "H:\Documents\GitHub\Assignment3\.venv\lib\site-packages\uvicorn\protocols\http\httptools_impl.py", line 372, in run_asgi
    result = await app(self.scope, self.receive, self.send)
  File "H:\Documents\GitHub\Assignment3\.venv\lib\site-packages\uvicorn\middleware\proxy_headers.py", line 75, in __call__
    return await self.app(scope, receive, send)
  File "H:\Documents\GitHub\Assignment3\.venv\lib\site-packages\fastapi\applications.py", line 269, in __call__
    await super().__call__(scope, receive, send)
  File "H:\Documents\GitHub\Assignment3\.venv\lib\site-packages\starlette\applications.py", line 124, in __call__
    await self.middleware_stack(scope, receive, send)
  File "H:\Documents\GitHub\Assignment3\.venv\lib\site-packages\starlette\middleware\errors.py", line 184, in __call__
    raise exc
  File "H:\Documents\GitHub\Assignment3\.venv\lib\site-packages\starlette\middleware\errors.py", line 162, in __call__
    await self.app(scope, receive, _send)
  File "H:\Documents\GitHub\Assignment3\.venv\lib\site-packages\starlette\middleware\base.py", line 68, in __call__
    response = await self.dispatch_func(request, call_next)
  File "H:\Documents\GitHub\Assignment3\src\.\main.py", line 245, in log_requests
    response = await call_next(request)
  File "H:\Documents\GitHub\Assignment3\.venv\lib\site-packages\starlette\middleware\base.py", line 46, in call_next
    raise app_exc
  File "H:\Documents\GitHub\Assignment3\.venv\lib\site-packages\starlette\middleware\base.py", line 36, in coro
    await self.app(scope, request.receive, send_stream.send)
  File "H:\Documents\GitHub\Assignment3\.venv\lib\site-packages\starlette\exceptions.py", line 93, in __call__
    raise exc
  File "H:\Documents\GitHub\Assignment3\.venv\lib\site-packages\starlette\exceptions.py", line 82, in __call__
    await self.app(scope, receive, sender)
  File "H:\Documents\GitHub\Assignment3\.venv\lib\site-packages\fastapi\middleware\asyncexitstack.py", line 21, in __call__
    raise e
  File "H:\Documents\GitHub\Assignment3\.venv\lib\site-packages\fastapi\middleware\asyncexitstack.py", line 18, in __call__
    await self.app(scope, receive, send)
  File "H:\Documents\GitHub\Assignment3\.venv\lib\site-packages\starlette\routing.py", line 670, in __call__
    await route.handle(scope, receive, send)
  File "H:\Documents\GitHub\Assignment3\.venv\lib\site-packages\starlette\routing.py", line 266, in handle
    await self.app(scope, receive, send)
  File "H:\Documents\GitHub\Assignment3\.venv\lib\site-packages\starlette\routing.py", line 65, in app
    response = await func(request)
  File "H:\Documents\GitHub\Assignment3\.venv\lib\site-packages\fastapi\routing.py", line 227, in app
    raw_response = await run_endpoint_function(
  File "H:\Documents\GitHub\Assignment3\.venv\lib\site-packages\fastapi\routing.py", line 160, in run_endpoint_function
    return await dependant.call(**values)
  File "H:\Documents\GitHub\Assignment3\src\.\main.py", line 305, in qualityinspection
    response = test_model.qualityinspection(file)
  File "H:\Documents\GitHub\Assignment3\src\api_functions\test_model.py", line 16, in qualityinspection
    with open('./model_pkl', 'rb') as file:
FileNotFoundError: [Errno 2] No such file or directory: './model_pkl'
2022-07-15 01:37:49,098 loglevel=INFO   Started server process [14148]
2022-07-15 01:37:49,098 loglevel=INFO   Waiting for application startup.
2022-07-15 01:37:49,099 loglevel=INFO   Application startup complete.
2022-07-15 01:37:50,441 loglevel=ERROR  Exception in ASGI application
Traceback (most recent call last):
  File "H:\Documents\GitHub\Assignment3\.venv\lib\site-packages\starlette\middleware\base.py", line 43, in call_next
    message = await recv_stream.receive()
  File "H:\Documents\GitHub\Assignment3\.venv\lib\site-packages\anyio\streams\memory.py", line 94, in receive
    return self.receive_nowait()
  File "H:\Documents\GitHub\Assignment3\.venv\lib\site-packages\anyio\streams\memory.py", line 87, in receive_nowait
    raise EndOfStream
anyio.EndOfStream

During handling of the above exception, another exception occurred:

Traceback (most recent call last):
  File "H:\Documents\GitHub\Assignment3\.venv\lib\site-packages\uvicorn\protocols\http\httptools_impl.py", line 372, in run_asgi
    result = await app(self.scope, self.receive, self.send)
  File "H:\Documents\GitHub\Assignment3\.venv\lib\site-packages\uvicorn\middleware\proxy_headers.py", line 75, in __call__
    return await self.app(scope, receive, send)
  File "H:\Documents\GitHub\Assignment3\.venv\lib\site-packages\fastapi\applications.py", line 269, in __call__
    await super().__call__(scope, receive, send)
  File "H:\Documents\GitHub\Assignment3\.venv\lib\site-packages\starlette\applications.py", line 124, in __call__
    await self.middleware_stack(scope, receive, send)
  File "H:\Documents\GitHub\Assignment3\.venv\lib\site-packages\starlette\middleware\errors.py", line 184, in __call__
    raise exc
  File "H:\Documents\GitHub\Assignment3\.venv\lib\site-packages\starlette\middleware\errors.py", line 162, in __call__
    await self.app(scope, receive, _send)
  File "H:\Documents\GitHub\Assignment3\.venv\lib\site-packages\starlette\middleware\base.py", line 68, in __call__
    response = await self.dispatch_func(request, call_next)
  File "H:\Documents\GitHub\Assignment3\src\.\main.py", line 245, in log_requests
    response = await call_next(request)
  File "H:\Documents\GitHub\Assignment3\.venv\lib\site-packages\starlette\middleware\base.py", line 46, in call_next
    raise app_exc
  File "H:\Documents\GitHub\Assignment3\.venv\lib\site-packages\starlette\middleware\base.py", line 36, in coro
    await self.app(scope, request.receive, send_stream.send)
  File "H:\Documents\GitHub\Assignment3\.venv\lib\site-packages\starlette\exceptions.py", line 93, in __call__
    raise exc
  File "H:\Documents\GitHub\Assignment3\.venv\lib\site-packages\starlette\exceptions.py", line 82, in __call__
    await self.app(scope, receive, sender)
  File "H:\Documents\GitHub\Assignment3\.venv\lib\site-packages\fastapi\middleware\asyncexitstack.py", line 21, in __call__
    raise e
  File "H:\Documents\GitHub\Assignment3\.venv\lib\site-packages\fastapi\middleware\asyncexitstack.py", line 18, in __call__
    await self.app(scope, receive, send)
  File "H:\Documents\GitHub\Assignment3\.venv\lib\site-packages\starlette\routing.py", line 670, in __call__
    await route.handle(scope, receive, send)
  File "H:\Documents\GitHub\Assignment3\.venv\lib\site-packages\starlette\routing.py", line 266, in handle
    await self.app(scope, receive, send)
  File "H:\Documents\GitHub\Assignment3\.venv\lib\site-packages\starlette\routing.py", line 65, in app
    response = await func(request)
  File "H:\Documents\GitHub\Assignment3\.venv\lib\site-packages\fastapi\routing.py", line 227, in app
    raw_response = await run_endpoint_function(
  File "H:\Documents\GitHub\Assignment3\.venv\lib\site-packages\fastapi\routing.py", line 160, in run_endpoint_function
    return await dependant.call(**values)
  File "H:\Documents\GitHub\Assignment3\src\.\main.py", line 305, in qualityinspection
    response = test_model.qualityinspection(file)
  File "H:\Documents\GitHub\Assignment3\src\api_functions\test_model.py", line 16, in qualityinspection
    with open('./model_pkl.pkl', 'rb') as file:
FileNotFoundError: [Errno 2] No such file or directory: './model_pkl.pkl'
2022-07-15 01:39:09,852 loglevel=INFO   Started server process [9128]
2022-07-15 01:39:09,853 loglevel=INFO   Waiting for application startup.
2022-07-15 01:39:09,853 loglevel=INFO   Application startup complete.
2022-07-15 01:39:16,182 loglevel=ERROR  Exception in ASGI application
Traceback (most recent call last):
  File "H:\Documents\GitHub\Assignment3\.venv\lib\site-packages\starlette\middleware\base.py", line 43, in call_next
    message = await recv_stream.receive()
  File "H:\Documents\GitHub\Assignment3\.venv\lib\site-packages\anyio\streams\memory.py", line 94, in receive
    return self.receive_nowait()
  File "H:\Documents\GitHub\Assignment3\.venv\lib\site-packages\anyio\streams\memory.py", line 87, in receive_nowait
    raise EndOfStream
anyio.EndOfStream

During handling of the above exception, another exception occurred:

Traceback (most recent call last):
  File "H:\Documents\GitHub\Assignment3\.venv\lib\site-packages\uvicorn\protocols\http\httptools_impl.py", line 372, in run_asgi
    result = await app(self.scope, self.receive, self.send)
  File "H:\Documents\GitHub\Assignment3\.venv\lib\site-packages\uvicorn\middleware\proxy_headers.py", line 75, in __call__
    return await self.app(scope, receive, send)
  File "H:\Documents\GitHub\Assignment3\.venv\lib\site-packages\fastapi\applications.py", line 269, in __call__
    await super().__call__(scope, receive, send)
  File "H:\Documents\GitHub\Assignment3\.venv\lib\site-packages\starlette\applications.py", line 124, in __call__
    await self.middleware_stack(scope, receive, send)
  File "H:\Documents\GitHub\Assignment3\.venv\lib\site-packages\starlette\middleware\errors.py", line 184, in __call__
    raise exc
  File "H:\Documents\GitHub\Assignment3\.venv\lib\site-packages\starlette\middleware\errors.py", line 162, in __call__
    await self.app(scope, receive, _send)
  File "H:\Documents\GitHub\Assignment3\.venv\lib\site-packages\starlette\middleware\base.py", line 68, in __call__
    response = await self.dispatch_func(request, call_next)
  File "H:\Documents\GitHub\Assignment3\src\.\main.py", line 245, in log_requests
    response = await call_next(request)
  File "H:\Documents\GitHub\Assignment3\.venv\lib\site-packages\starlette\middleware\base.py", line 46, in call_next
    raise app_exc
  File "H:\Documents\GitHub\Assignment3\.venv\lib\site-packages\starlette\middleware\base.py", line 36, in coro
    await self.app(scope, request.receive, send_stream.send)
  File "H:\Documents\GitHub\Assignment3\.venv\lib\site-packages\starlette\exceptions.py", line 93, in __call__
    raise exc
  File "H:\Documents\GitHub\Assignment3\.venv\lib\site-packages\starlette\exceptions.py", line 82, in __call__
    await self.app(scope, receive, sender)
  File "H:\Documents\GitHub\Assignment3\.venv\lib\site-packages\fastapi\middleware\asyncexitstack.py", line 21, in __call__
    raise e
  File "H:\Documents\GitHub\Assignment3\.venv\lib\site-packages\fastapi\middleware\asyncexitstack.py", line 18, in __call__
    await self.app(scope, receive, send)
  File "H:\Documents\GitHub\Assignment3\.venv\lib\site-packages\starlette\routing.py", line 670, in __call__
    await route.handle(scope, receive, send)
  File "H:\Documents\GitHub\Assignment3\.venv\lib\site-packages\starlette\routing.py", line 266, in handle
    await self.app(scope, receive, send)
  File "H:\Documents\GitHub\Assignment3\.venv\lib\site-packages\starlette\routing.py", line 65, in app
    response = await func(request)
  File "H:\Documents\GitHub\Assignment3\.venv\lib\site-packages\fastapi\routing.py", line 227, in app
    raw_response = await run_endpoint_function(
  File "H:\Documents\GitHub\Assignment3\.venv\lib\site-packages\fastapi\routing.py", line 160, in run_endpoint_function
    return await dependant.call(**values)
  File "H:\Documents\GitHub\Assignment3\src\.\main.py", line 305, in qualityinspection
    response = test_model.qualityinspection(file)
  File "H:\Documents\GitHub\Assignment3\src\api_functions\test_model.py", line 16, in qualityinspection
    with open('./model_pkl', 'rb') as file:
FileNotFoundError: [Errno 2] No such file or directory: './model_pkl'
2022-07-15 01:39:33,155 loglevel=INFO   Started server process [2356]
2022-07-15 01:39:33,156 loglevel=INFO   Waiting for application startup.
2022-07-15 01:39:33,156 loglevel=INFO   Application startup complete.
2022-07-15 01:39:36,154 loglevel=ERROR  Exception in ASGI application
Traceback (most recent call last):
  File "H:\Documents\GitHub\Assignment3\.venv\lib\site-packages\starlette\middleware\base.py", line 43, in call_next
    message = await recv_stream.receive()
  File "H:\Documents\GitHub\Assignment3\.venv\lib\site-packages\anyio\streams\memory.py", line 94, in receive
    return self.receive_nowait()
  File "H:\Documents\GitHub\Assignment3\.venv\lib\site-packages\anyio\streams\memory.py", line 87, in receive_nowait
    raise EndOfStream
anyio.EndOfStream

During handling of the above exception, another exception occurred:

Traceback (most recent call last):
  File "H:\Documents\GitHub\Assignment3\.venv\lib\site-packages\uvicorn\protocols\http\httptools_impl.py", line 372, in run_asgi
    result = await app(self.scope, self.receive, self.send)
  File "H:\Documents\GitHub\Assignment3\.venv\lib\site-packages\uvicorn\middleware\proxy_headers.py", line 75, in __call__
    return await self.app(scope, receive, send)
  File "H:\Documents\GitHub\Assignment3\.venv\lib\site-packages\fastapi\applications.py", line 269, in __call__
    await super().__call__(scope, receive, send)
  File "H:\Documents\GitHub\Assignment3\.venv\lib\site-packages\starlette\applications.py", line 124, in __call__
    await self.middleware_stack(scope, receive, send)
  File "H:\Documents\GitHub\Assignment3\.venv\lib\site-packages\starlette\middleware\errors.py", line 184, in __call__
    raise exc
  File "H:\Documents\GitHub\Assignment3\.venv\lib\site-packages\starlette\middleware\errors.py", line 162, in __call__
    await self.app(scope, receive, _send)
  File "H:\Documents\GitHub\Assignment3\.venv\lib\site-packages\starlette\middleware\base.py", line 68, in __call__
    response = await self.dispatch_func(request, call_next)
  File "H:\Documents\GitHub\Assignment3\src\.\main.py", line 245, in log_requests
    response = await call_next(request)
  File "H:\Documents\GitHub\Assignment3\.venv\lib\site-packages\starlette\middleware\base.py", line 46, in call_next
    raise app_exc
  File "H:\Documents\GitHub\Assignment3\.venv\lib\site-packages\starlette\middleware\base.py", line 36, in coro
    await self.app(scope, request.receive, send_stream.send)
  File "H:\Documents\GitHub\Assignment3\.venv\lib\site-packages\starlette\exceptions.py", line 93, in __call__
    raise exc
  File "H:\Documents\GitHub\Assignment3\.venv\lib\site-packages\starlette\exceptions.py", line 82, in __call__
    await self.app(scope, receive, sender)
  File "H:\Documents\GitHub\Assignment3\.venv\lib\site-packages\fastapi\middleware\asyncexitstack.py", line 21, in __call__
    raise e
  File "H:\Documents\GitHub\Assignment3\.venv\lib\site-packages\fastapi\middleware\asyncexitstack.py", line 18, in __call__
    await self.app(scope, receive, send)
  File "H:\Documents\GitHub\Assignment3\.venv\lib\site-packages\starlette\routing.py", line 670, in __call__
    await route.handle(scope, receive, send)
  File "H:\Documents\GitHub\Assignment3\.venv\lib\site-packages\starlette\routing.py", line 266, in handle
    await self.app(scope, receive, send)
  File "H:\Documents\GitHub\Assignment3\.venv\lib\site-packages\starlette\routing.py", line 65, in app
    response = await func(request)
  File "H:\Documents\GitHub\Assignment3\.venv\lib\site-packages\fastapi\routing.py", line 227, in app
    raw_response = await run_endpoint_function(
  File "H:\Documents\GitHub\Assignment3\.venv\lib\site-packages\fastapi\routing.py", line 160, in run_endpoint_function
    return await dependant.call(**values)
  File "H:\Documents\GitHub\Assignment3\src\.\main.py", line 305, in qualityinspection
    response = test_model.qualityinspection(file)
  File "H:\Documents\GitHub\Assignment3\src\api_functions\test_model.py", line 16, in qualityinspection
    with open('\\model_pkl', 'rb') as file:
FileNotFoundError: [Errno 2] No such file or directory: '\\model_pkl'
2022-07-15 01:41:50,854 loglevel=INFO   Started server process [16252]
2022-07-15 01:41:50,854 loglevel=INFO   Waiting for application startup.
2022-07-15 01:41:50,855 loglevel=INFO   Application startup complete.
2022-07-15 01:42:06,910 loglevel=ERROR  Exception in ASGI application
Traceback (most recent call last):
  File "H:\Documents\GitHub\Assignment3\.venv\lib\site-packages\starlette\middleware\base.py", line 43, in call_next
    message = await recv_stream.receive()
  File "H:\Documents\GitHub\Assignment3\.venv\lib\site-packages\anyio\streams\memory.py", line 94, in receive
    return self.receive_nowait()
  File "H:\Documents\GitHub\Assignment3\.venv\lib\site-packages\anyio\streams\memory.py", line 87, in receive_nowait
    raise EndOfStream
anyio.EndOfStream

During handling of the above exception, another exception occurred:

Traceback (most recent call last):
  File "H:\Documents\GitHub\Assignment3\.venv\lib\site-packages\uvicorn\protocols\http\httptools_impl.py", line 372, in run_asgi
    result = await app(self.scope, self.receive, self.send)
  File "H:\Documents\GitHub\Assignment3\.venv\lib\site-packages\uvicorn\middleware\proxy_headers.py", line 75, in __call__
    return await self.app(scope, receive, send)
  File "H:\Documents\GitHub\Assignment3\.venv\lib\site-packages\fastapi\applications.py", line 269, in __call__
    await super().__call__(scope, receive, send)
  File "H:\Documents\GitHub\Assignment3\.venv\lib\site-packages\starlette\applications.py", line 124, in __call__
    await self.middleware_stack(scope, receive, send)
  File "H:\Documents\GitHub\Assignment3\.venv\lib\site-packages\starlette\middleware\errors.py", line 184, in __call__
    raise exc
  File "H:\Documents\GitHub\Assignment3\.venv\lib\site-packages\starlette\middleware\errors.py", line 162, in __call__
    await self.app(scope, receive, _send)
  File "H:\Documents\GitHub\Assignment3\.venv\lib\site-packages\starlette\middleware\base.py", line 68, in __call__
    response = await self.dispatch_func(request, call_next)
  File "H:\Documents\GitHub\Assignment3\src\.\main.py", line 245, in log_requests
    response = await call_next(request)
  File "H:\Documents\GitHub\Assignment3\.venv\lib\site-packages\starlette\middleware\base.py", line 46, in call_next
    raise app_exc
  File "H:\Documents\GitHub\Assignment3\.venv\lib\site-packages\starlette\middleware\base.py", line 36, in coro
    await self.app(scope, request.receive, send_stream.send)
  File "H:\Documents\GitHub\Assignment3\.venv\lib\site-packages\starlette\exceptions.py", line 93, in __call__
    raise exc
  File "H:\Documents\GitHub\Assignment3\.venv\lib\site-packages\starlette\exceptions.py", line 82, in __call__
    await self.app(scope, receive, sender)
  File "H:\Documents\GitHub\Assignment3\.venv\lib\site-packages\fastapi\middleware\asyncexitstack.py", line 21, in __call__
    raise e
  File "H:\Documents\GitHub\Assignment3\.venv\lib\site-packages\fastapi\middleware\asyncexitstack.py", line 18, in __call__
    await self.app(scope, receive, send)
  File "H:\Documents\GitHub\Assignment3\.venv\lib\site-packages\starlette\routing.py", line 670, in __call__
    await route.handle(scope, receive, send)
  File "H:\Documents\GitHub\Assignment3\.venv\lib\site-packages\starlette\routing.py", line 266, in handle
    await self.app(scope, receive, send)
  File "H:\Documents\GitHub\Assignment3\.venv\lib\site-packages\starlette\routing.py", line 65, in app
    response = await func(request)
  File "H:\Documents\GitHub\Assignment3\.venv\lib\site-packages\fastapi\routing.py", line 227, in app
    raw_response = await run_endpoint_function(
  File "H:\Documents\GitHub\Assignment3\.venv\lib\site-packages\fastapi\routing.py", line 160, in run_endpoint_function
    return await dependant.call(**values)
  File "H:\Documents\GitHub\Assignment3\src\.\main.py", line 305, in qualityinspection
    response = test_model.qualityinspection(file)
  File "H:\Documents\GitHub\Assignment3\src\api_functions\test_model.py", line 16, in qualityinspection
    with open('model_pkl', 'rb') as file:
FileNotFoundError: [Errno 2] No such file or directory: 'model_pkl'
2022-07-15 01:44:30,362 loglevel=INFO   Started server process [12568]
2022-07-15 01:44:30,363 loglevel=INFO   Waiting for application startup.
2022-07-15 01:44:30,363 loglevel=INFO   Application startup complete.
2022-07-15 01:44:30,619 loglevel=INFO   rid=Z0RFUU request url=http://127.0.0.1:8000/ completed_in=1.00ms status_code=200
2022-07-15 01:44:31,743 loglevel=INFO   rid=6E0ABB request url=http://127.0.0.1:8000/docs completed_in=0.00ms status_code=200
2022-07-15 01:44:31,807 loglevel=INFO   rid=U4R9A2 request url=http://127.0.0.1:8000/openapi.json completed_in=3.00ms status_code=200
2022-07-15 01:44:38,751 loglevel=ERROR  Exception in ASGI application
Traceback (most recent call last):
  File "H:\Documents\GitHub\Assignment3\.venv\lib\site-packages\anyio\streams\memory.py", line 94, in receive
    return self.receive_nowait()
  File "H:\Documents\GitHub\Assignment3\.venv\lib\site-packages\anyio\streams\memory.py", line 89, in receive_nowait
    raise WouldBlock
anyio.WouldBlock

During handling of the above exception, another exception occurred:

Traceback (most recent call last):
  File "H:\Documents\GitHub\Assignment3\.venv\lib\site-packages\starlette\middleware\base.py", line 43, in call_next
    message = await recv_stream.receive()
  File "H:\Documents\GitHub\Assignment3\.venv\lib\site-packages\anyio\streams\memory.py", line 114, in receive
    raise EndOfStream
anyio.EndOfStream

During handling of the above exception, another exception occurred:

Traceback (most recent call last):
  File "H:\Documents\GitHub\Assignment3\.venv\lib\site-packages\uvicorn\protocols\http\httptools_impl.py", line 372, in run_asgi
    result = await app(self.scope, self.receive, self.send)
  File "H:\Documents\GitHub\Assignment3\.venv\lib\site-packages\uvicorn\middleware\proxy_headers.py", line 75, in __call__
    return await self.app(scope, receive, send)
  File "H:\Documents\GitHub\Assignment3\.venv\lib\site-packages\fastapi\applications.py", line 269, in __call__
    await super().__call__(scope, receive, send)
  File "H:\Documents\GitHub\Assignment3\.venv\lib\site-packages\starlette\applications.py", line 124, in __call__
    await self.middleware_stack(scope, receive, send)
  File "H:\Documents\GitHub\Assignment3\.venv\lib\site-packages\starlette\middleware\errors.py", line 184, in __call__
    raise exc
  File "H:\Documents\GitHub\Assignment3\.venv\lib\site-packages\starlette\middleware\errors.py", line 162, in __call__
    await self.app(scope, receive, _send)
  File "H:\Documents\GitHub\Assignment3\.venv\lib\site-packages\starlette\middleware\base.py", line 68, in __call__
    response = await self.dispatch_func(request, call_next)
  File "H:\Documents\GitHub\Assignment3\src\.\main.py", line 245, in log_requests
    response = await call_next(request)
  File "H:\Documents\GitHub\Assignment3\.venv\lib\site-packages\starlette\middleware\base.py", line 46, in call_next
    raise app_exc
  File "H:\Documents\GitHub\Assignment3\.venv\lib\site-packages\starlette\middleware\base.py", line 36, in coro
    await self.app(scope, request.receive, send_stream.send)
  File "H:\Documents\GitHub\Assignment3\.venv\lib\site-packages\starlette\exceptions.py", line 93, in __call__
    raise exc
  File "H:\Documents\GitHub\Assignment3\.venv\lib\site-packages\starlette\exceptions.py", line 82, in __call__
    await self.app(scope, receive, sender)
  File "H:\Documents\GitHub\Assignment3\.venv\lib\site-packages\fastapi\middleware\asyncexitstack.py", line 21, in __call__
    raise e
  File "H:\Documents\GitHub\Assignment3\.venv\lib\site-packages\fastapi\middleware\asyncexitstack.py", line 18, in __call__
    await self.app(scope, receive, send)
  File "H:\Documents\GitHub\Assignment3\.venv\lib\site-packages\starlette\routing.py", line 670, in __call__
    await route.handle(scope, receive, send)
  File "H:\Documents\GitHub\Assignment3\.venv\lib\site-packages\starlette\routing.py", line 266, in handle
    await self.app(scope, receive, send)
  File "H:\Documents\GitHub\Assignment3\.venv\lib\site-packages\starlette\routing.py", line 65, in app
    response = await func(request)
  File "H:\Documents\GitHub\Assignment3\.venv\lib\site-packages\fastapi\routing.py", line 227, in app
    raw_response = await run_endpoint_function(
  File "H:\Documents\GitHub\Assignment3\.venv\lib\site-packages\fastapi\routing.py", line 160, in run_endpoint_function
    return await dependant.call(**values)
  File "H:\Documents\GitHub\Assignment3\src\.\main.py", line 305, in qualityinspection
    response = test_model.qualityinspection(file)
  File "H:\Documents\GitHub\Assignment3\src\api_functions\test_model.py", line 14, in qualityinspection
    model = joblib.load('H:\Documents\GitHub\Assignment3\src\api_functions\model_pkl')
  File "H:\Documents\GitHub\Assignment3\.venv\lib\site-packages\joblib\numpy_pickle.py", line 579, in load
    with open(filename, 'rb') as f:
OSError: [Errno 22] Invalid argument: 'H:\\Documents\\GitHub\\Assignment3\\src\x07pi_functions\\model_pkl'
2022-07-15 01:45:16,579 loglevel=INFO   Started server process [3380]
2022-07-15 01:45:16,579 loglevel=INFO   Waiting for application startup.
2022-07-15 01:45:16,580 loglevel=INFO   Application startup complete.
2022-07-15 01:45:23,896 loglevel=ERROR  Exception in ASGI application
Traceback (most recent call last):
  File "H:\Documents\GitHub\Assignment3\.venv\lib\site-packages\uvicorn\protocols\http\httptools_impl.py", line 372, in run_asgi
    result = await app(self.scope, self.receive, self.send)
  File "H:\Documents\GitHub\Assignment3\.venv\lib\site-packages\uvicorn\middleware\proxy_headers.py", line 75, in __call__
    return await self.app(scope, receive, send)
  File "H:\Documents\GitHub\Assignment3\.venv\lib\site-packages\fastapi\applications.py", line 269, in __call__
    await super().__call__(scope, receive, send)
  File "H:\Documents\GitHub\Assignment3\.venv\lib\site-packages\starlette\applications.py", line 124, in __call__
    await self.middleware_stack(scope, receive, send)
  File "H:\Documents\GitHub\Assignment3\.venv\lib\site-packages\starlette\middleware\errors.py", line 184, in __call__
    raise exc
  File "H:\Documents\GitHub\Assignment3\.venv\lib\site-packages\starlette\middleware\errors.py", line 162, in __call__
    await self.app(scope, receive, _send)
  File "H:\Documents\GitHub\Assignment3\.venv\lib\site-packages\starlette\middleware\base.py", line 68, in __call__
    response = await self.dispatch_func(request, call_next)
  File "H:\Documents\GitHub\Assignment3\src\.\main.py", line 245, in log_requests
    response = await call_next(request)
  File "H:\Documents\GitHub\Assignment3\.venv\lib\site-packages\starlette\middleware\base.py", line 46, in call_next
    raise app_exc
  File "H:\Documents\GitHub\Assignment3\.venv\lib\site-packages\starlette\middleware\base.py", line 36, in coro
    await self.app(scope, request.receive, send_stream.send)
  File "H:\Documents\GitHub\Assignment3\.venv\lib\site-packages\starlette\exceptions.py", line 93, in __call__
    raise exc
  File "H:\Documents\GitHub\Assignment3\.venv\lib\site-packages\starlette\exceptions.py", line 82, in __call__
    await self.app(scope, receive, sender)
  File "H:\Documents\GitHub\Assignment3\.venv\lib\site-packages\fastapi\middleware\asyncexitstack.py", line 21, in __call__
    raise e
  File "H:\Documents\GitHub\Assignment3\.venv\lib\site-packages\fastapi\middleware\asyncexitstack.py", line 18, in __call__
    await self.app(scope, receive, send)
  File "H:\Documents\GitHub\Assignment3\.venv\lib\site-packages\starlette\routing.py", line 670, in __call__
    await route.handle(scope, receive, send)
  File "H:\Documents\GitHub\Assignment3\.venv\lib\site-packages\starlette\routing.py", line 266, in handle
    await self.app(scope, receive, send)
  File "H:\Documents\GitHub\Assignment3\.venv\lib\site-packages\starlette\routing.py", line 65, in app
    response = await func(request)
  File "H:\Documents\GitHub\Assignment3\.venv\lib\site-packages\fastapi\routing.py", line 227, in app
    raw_response = await run_endpoint_function(
  File "H:\Documents\GitHub\Assignment3\.venv\lib\site-packages\fastapi\routing.py", line 160, in run_endpoint_function
    return await dependant.call(**values)
  File "H:\Documents\GitHub\Assignment3\src\.\main.py", line 305, in qualityinspection
    response = test_model.qualityinspection(file)
  File "H:\Documents\GitHub\Assignment3\src\api_functions\test_model.py", line 14, in qualityinspection
    model = joblib.load('H:\\Documents\\GitHub\\Assignment3\\src\\api_functions\\model_pkl')
  File "H:\Documents\GitHub\Assignment3\.venv\lib\site-packages\joblib\numpy_pickle.py", line 587, in load
    obj = _unpickle(fobj, filename, mmap_mode)
  File "H:\Documents\GitHub\Assignment3\.venv\lib\site-packages\joblib\numpy_pickle.py", line 506, in _unpickle
    obj = unpickler.load()
  File "C:\Program Files\WindowsApps\PythonSoftwareFoundation.Python.3.10_3.10.1520.0_x64__qbz5n2kfra8p0\lib\pickle.py", line 1213, in load
    dispatch[key[0]](self)
  File "C:\Program Files\WindowsApps\PythonSoftwareFoundation.Python.3.10_3.10.1520.0_x64__qbz5n2kfra8p0\lib\pickle.py", line 1590, in load_reduce
    stack[-1] = func(*args)
  File "H:\Documents\GitHub\Assignment3\.venv\lib\site-packages\keras\saving\pickle_utils.py", line 48, in deserialize_model_from_bytecode
    model = save_module.load_model(temp_dir)
  File "H:\Documents\GitHub\Assignment3\.venv\lib\site-packages\keras\utils\traceback_utils.py", line 67, in error_handler
    raise e.with_traceback(filtered_tb) from None
  File "H:\Documents\GitHub\Assignment3\.venv\lib\site-packages\tensorflow\python\saved_model\load.py", line 915, in load_partial
    raise FileNotFoundError(
FileNotFoundError: Unsuccessful TensorSliceReader constructor: Failed to find any matching files for ram://08212a48-e349-4eec-8f65-5ad250bb2bf1/variables/variables
 You may be trying to load on a different device from the computational device. Consider setting the `experimental_io_device` option in `tf.saved_model.LoadOptions` to the io_device such as '/job:localhost'.
2022-07-15 01:47:33,401 loglevel=INFO   Started server process [12052]
2022-07-15 01:47:33,401 loglevel=INFO   Waiting for application startup.
2022-07-15 01:47:33,402 loglevel=INFO   Application startup complete.
2022-07-15 01:56:52,746 loglevel=INFO   Started server process [968]
2022-07-15 01:56:52,746 loglevel=INFO   Waiting for application startup.
2022-07-15 01:56:52,747 loglevel=INFO   Application startup complete.
2022-07-15 01:56:52,880 loglevel=INFO   rid=DPKUZH request url=http://127.0.0.1:8000/ completed_in=0.00ms status_code=200
2022-07-15 01:56:59,090 loglevel=INFO   rid=5HSB51 request url=http://127.0.0.1:8000/docs completed_in=1.00ms status_code=200
2022-07-15 01:56:59,152 loglevel=INFO   rid=MBWVZ6 request url=http://127.0.0.1:8000/openapi.json completed_in=4.00ms status_code=200
2022-07-15 01:57:15,050 loglevel=ERROR  Exception in ASGI application
Traceback (most recent call last):
  File "H:\Documents\GitHub\Assignment3\.venv\lib\site-packages\uvicorn\protocols\http\httptools_impl.py", line 372, in run_asgi
    result = await app(self.scope, self.receive, self.send)
  File "H:\Documents\GitHub\Assignment3\.venv\lib\site-packages\uvicorn\middleware\proxy_headers.py", line 75, in __call__
    return await self.app(scope, receive, send)
  File "H:\Documents\GitHub\Assignment3\.venv\lib\site-packages\fastapi\applications.py", line 269, in __call__
    await super().__call__(scope, receive, send)
  File "H:\Documents\GitHub\Assignment3\.venv\lib\site-packages\starlette\applications.py", line 124, in __call__
    await self.middleware_stack(scope, receive, send)
  File "H:\Documents\GitHub\Assignment3\.venv\lib\site-packages\starlette\middleware\errors.py", line 184, in __call__
    raise exc
  File "H:\Documents\GitHub\Assignment3\.venv\lib\site-packages\starlette\middleware\errors.py", line 162, in __call__
    await self.app(scope, receive, _send)
  File "H:\Documents\GitHub\Assignment3\.venv\lib\site-packages\starlette\middleware\base.py", line 68, in __call__
    response = await self.dispatch_func(request, call_next)
  File "H:\Documents\GitHub\Assignment3\src\.\main.py", line 245, in log_requests
    response = await call_next(request)
  File "H:\Documents\GitHub\Assignment3\.venv\lib\site-packages\starlette\middleware\base.py", line 46, in call_next
    raise app_exc
  File "H:\Documents\GitHub\Assignment3\.venv\lib\site-packages\starlette\middleware\base.py", line 36, in coro
    await self.app(scope, request.receive, send_stream.send)
  File "H:\Documents\GitHub\Assignment3\.venv\lib\site-packages\starlette\exceptions.py", line 93, in __call__
    raise exc
  File "H:\Documents\GitHub\Assignment3\.venv\lib\site-packages\starlette\exceptions.py", line 82, in __call__
    await self.app(scope, receive, sender)
  File "H:\Documents\GitHub\Assignment3\.venv\lib\site-packages\fastapi\middleware\asyncexitstack.py", line 21, in __call__
    raise e
  File "H:\Documents\GitHub\Assignment3\.venv\lib\site-packages\fastapi\middleware\asyncexitstack.py", line 18, in __call__
    await self.app(scope, receive, send)
  File "H:\Documents\GitHub\Assignment3\.venv\lib\site-packages\starlette\routing.py", line 670, in __call__
    await route.handle(scope, receive, send)
  File "H:\Documents\GitHub\Assignment3\.venv\lib\site-packages\starlette\routing.py", line 266, in handle
    await self.app(scope, receive, send)
  File "H:\Documents\GitHub\Assignment3\.venv\lib\site-packages\starlette\routing.py", line 65, in app
    response = await func(request)
  File "H:\Documents\GitHub\Assignment3\.venv\lib\site-packages\fastapi\routing.py", line 227, in app
    raw_response = await run_endpoint_function(
  File "H:\Documents\GitHub\Assignment3\.venv\lib\site-packages\fastapi\routing.py", line 160, in run_endpoint_function
    return await dependant.call(**values)
  File "H:\Documents\GitHub\Assignment3\src\.\main.py", line 305, in qualityinspection
    response = test_model.qualityinspection(file)
  File "H:\Documents\GitHub\Assignment3\src\api_functions\test_model.py", line 14, in qualityinspection
    model = joblib.load('model.pkl')
  File "H:\Documents\GitHub\Assignment3\.venv\lib\site-packages\joblib\numpy_pickle.py", line 587, in load
    obj = _unpickle(fobj, filename, mmap_mode)
  File "H:\Documents\GitHub\Assignment3\.venv\lib\site-packages\joblib\numpy_pickle.py", line 506, in _unpickle
    obj = unpickler.load()
  File "C:\Program Files\WindowsApps\PythonSoftwareFoundation.Python.3.10_3.10.1520.0_x64__qbz5n2kfra8p0\lib\pickle.py", line 1213, in load
    dispatch[key[0]](self)
  File "C:\Program Files\WindowsApps\PythonSoftwareFoundation.Python.3.10_3.10.1520.0_x64__qbz5n2kfra8p0\lib\pickle.py", line 1590, in load_reduce
    stack[-1] = func(*args)
  File "H:\Documents\GitHub\Assignment3\.venv\lib\site-packages\keras\saving\pickle_utils.py", line 48, in deserialize_model_from_bytecode
    model = save_module.load_model(temp_dir)
  File "H:\Documents\GitHub\Assignment3\.venv\lib\site-packages\keras\utils\traceback_utils.py", line 67, in error_handler
    raise e.with_traceback(filtered_tb) from None
  File "H:\Documents\GitHub\Assignment3\.venv\lib\site-packages\tensorflow\python\saved_model\load.py", line 915, in load_partial
    raise FileNotFoundError(
FileNotFoundError: Unsuccessful TensorSliceReader constructor: Failed to find any matching files for ram://b4fcf204-45c5-4c1b-b04d-11e7d1ce6fbd/variables/variables
 You may be trying to load on a different device from the computational device. Consider setting the `experimental_io_device` option in `tf.saved_model.LoadOptions` to the io_device such as '/job:localhost'.
2022-07-15 01:59:00,364 loglevel=INFO   Started server process [2936]
2022-07-15 01:59:00,365 loglevel=INFO   Waiting for application startup.
2022-07-15 01:59:00,366 loglevel=INFO   Application startup complete.
2022-07-15 01:59:04,836 loglevel=INFO   rid=LCEOTK request url=http://127.0.0.1:8000/docs completed_in=0.00ms status_code=200
2022-07-15 01:59:04,907 loglevel=INFO   rid=WIQUI7 request url=http://127.0.0.1:8000/openapi.json completed_in=4.00ms status_code=200
2022-07-15 01:59:16,175 loglevel=ERROR  Exception in ASGI application
Traceback (most recent call last):
  File "H:\Documents\GitHub\Assignment3\.venv\lib\site-packages\uvicorn\protocols\http\httptools_impl.py", line 372, in run_asgi
    result = await app(self.scope, self.receive, self.send)
  File "H:\Documents\GitHub\Assignment3\.venv\lib\site-packages\uvicorn\middleware\proxy_headers.py", line 75, in __call__
    return await self.app(scope, receive, send)
  File "H:\Documents\GitHub\Assignment3\.venv\lib\site-packages\fastapi\applications.py", line 269, in __call__
    await super().__call__(scope, receive, send)
  File "H:\Documents\GitHub\Assignment3\.venv\lib\site-packages\starlette\applications.py", line 124, in __call__
    await self.middleware_stack(scope, receive, send)
  File "H:\Documents\GitHub\Assignment3\.venv\lib\site-packages\starlette\middleware\errors.py", line 184, in __call__
    raise exc
  File "H:\Documents\GitHub\Assignment3\.venv\lib\site-packages\starlette\middleware\errors.py", line 162, in __call__
    await self.app(scope, receive, _send)
  File "H:\Documents\GitHub\Assignment3\.venv\lib\site-packages\starlette\middleware\base.py", line 68, in __call__
    response = await self.dispatch_func(request, call_next)
  File "H:\Documents\GitHub\Assignment3\src\.\main.py", line 245, in log_requests
    response = await call_next(request)
  File "H:\Documents\GitHub\Assignment3\.venv\lib\site-packages\starlette\middleware\base.py", line 46, in call_next
    raise app_exc
  File "H:\Documents\GitHub\Assignment3\.venv\lib\site-packages\starlette\middleware\base.py", line 36, in coro
    await self.app(scope, request.receive, send_stream.send)
  File "H:\Documents\GitHub\Assignment3\.venv\lib\site-packages\starlette\exceptions.py", line 93, in __call__
    raise exc
  File "H:\Documents\GitHub\Assignment3\.venv\lib\site-packages\starlette\exceptions.py", line 82, in __call__
    await self.app(scope, receive, sender)
  File "H:\Documents\GitHub\Assignment3\.venv\lib\site-packages\fastapi\middleware\asyncexitstack.py", line 21, in __call__
    raise e
  File "H:\Documents\GitHub\Assignment3\.venv\lib\site-packages\fastapi\middleware\asyncexitstack.py", line 18, in __call__
    await self.app(scope, receive, send)
  File "H:\Documents\GitHub\Assignment3\.venv\lib\site-packages\starlette\routing.py", line 670, in __call__
    await route.handle(scope, receive, send)
  File "H:\Documents\GitHub\Assignment3\.venv\lib\site-packages\starlette\routing.py", line 266, in handle
    await self.app(scope, receive, send)
  File "H:\Documents\GitHub\Assignment3\.venv\lib\site-packages\starlette\routing.py", line 65, in app
    response = await func(request)
  File "H:\Documents\GitHub\Assignment3\.venv\lib\site-packages\fastapi\routing.py", line 227, in app
    raw_response = await run_endpoint_function(
  File "H:\Documents\GitHub\Assignment3\.venv\lib\site-packages\fastapi\routing.py", line 160, in run_endpoint_function
    return await dependant.call(**values)
  File "H:\Documents\GitHub\Assignment3\src\.\main.py", line 305, in qualityinspection
    response = test_model.qualityinspection(file)
  File "H:\Documents\GitHub\Assignment3\src\api_functions\test_model.py", line 14, in qualityinspection
    model = joblib.load('model.pkl')
  File "H:\Documents\GitHub\Assignment3\.venv\lib\site-packages\joblib\numpy_pickle.py", line 587, in load
    obj = _unpickle(fobj, filename, mmap_mode)
  File "H:\Documents\GitHub\Assignment3\.venv\lib\site-packages\joblib\numpy_pickle.py", line 506, in _unpickle
    obj = unpickler.load()
  File "C:\Program Files\WindowsApps\PythonSoftwareFoundation.Python.3.10_3.10.1520.0_x64__qbz5n2kfra8p0\lib\pickle.py", line 1213, in load
    dispatch[key[0]](self)
  File "C:\Program Files\WindowsApps\PythonSoftwareFoundation.Python.3.10_3.10.1520.0_x64__qbz5n2kfra8p0\lib\pickle.py", line 1590, in load_reduce
    stack[-1] = func(*args)
  File "H:\Documents\GitHub\Assignment3\.venv\lib\site-packages\keras\saving\pickle_utils.py", line 48, in deserialize_model_from_bytecode
    model = save_module.load_model(temp_dir)
  File "H:\Documents\GitHub\Assignment3\.venv\lib\site-packages\keras\utils\traceback_utils.py", line 67, in error_handler
    raise e.with_traceback(filtered_tb) from None
  File "H:\Documents\GitHub\Assignment3\.venv\lib\site-packages\tensorflow\python\saved_model\load.py", line 915, in load_partial
    raise FileNotFoundError(
FileNotFoundError: Unsuccessful TensorSliceReader constructor: Failed to find any matching files for ram://93e43ae0-020d-4762-99cd-ac6151256b89/variables/variables
 You may be trying to load on a different device from the computational device. Consider setting the `experimental_io_device` option in `tf.saved_model.LoadOptions` to the io_device such as '/job:localhost'.
2022-07-15 02:03:18,814 loglevel=INFO   Started server process [2276]
2022-07-15 02:03:18,814 loglevel=INFO   Waiting for application startup.
2022-07-15 02:03:18,815 loglevel=INFO   Application startup complete.
2022-07-15 02:03:29,888 loglevel=ERROR  Exception in ASGI application
Traceback (most recent call last):
  File "H:\Documents\GitHub\Assignment3\.venv\lib\site-packages\uvicorn\protocols\http\httptools_impl.py", line 372, in run_asgi
    result = await app(self.scope, self.receive, self.send)
  File "H:\Documents\GitHub\Assignment3\.venv\lib\site-packages\uvicorn\middleware\proxy_headers.py", line 75, in __call__
    return await self.app(scope, receive, send)
  File "H:\Documents\GitHub\Assignment3\.venv\lib\site-packages\fastapi\applications.py", line 269, in __call__
    await super().__call__(scope, receive, send)
  File "H:\Documents\GitHub\Assignment3\.venv\lib\site-packages\starlette\applications.py", line 124, in __call__
    await self.middleware_stack(scope, receive, send)
  File "H:\Documents\GitHub\Assignment3\.venv\lib\site-packages\starlette\middleware\errors.py", line 184, in __call__
    raise exc
  File "H:\Documents\GitHub\Assignment3\.venv\lib\site-packages\starlette\middleware\errors.py", line 162, in __call__
    await self.app(scope, receive, _send)
  File "H:\Documents\GitHub\Assignment3\.venv\lib\site-packages\starlette\middleware\base.py", line 68, in __call__
    response = await self.dispatch_func(request, call_next)
  File "H:\Documents\GitHub\Assignment3\src\.\main.py", line 245, in log_requests
    response = await call_next(request)
  File "H:\Documents\GitHub\Assignment3\.venv\lib\site-packages\starlette\middleware\base.py", line 46, in call_next
    raise app_exc
  File "H:\Documents\GitHub\Assignment3\.venv\lib\site-packages\starlette\middleware\base.py", line 36, in coro
    await self.app(scope, request.receive, send_stream.send)
  File "H:\Documents\GitHub\Assignment3\.venv\lib\site-packages\starlette\exceptions.py", line 93, in __call__
    raise exc
  File "H:\Documents\GitHub\Assignment3\.venv\lib\site-packages\starlette\exceptions.py", line 82, in __call__
    await self.app(scope, receive, sender)
  File "H:\Documents\GitHub\Assignment3\.venv\lib\site-packages\fastapi\middleware\asyncexitstack.py", line 21, in __call__
    raise e
  File "H:\Documents\GitHub\Assignment3\.venv\lib\site-packages\fastapi\middleware\asyncexitstack.py", line 18, in __call__
    await self.app(scope, receive, send)
  File "H:\Documents\GitHub\Assignment3\.venv\lib\site-packages\starlette\routing.py", line 670, in __call__
    await route.handle(scope, receive, send)
  File "H:\Documents\GitHub\Assignment3\.venv\lib\site-packages\starlette\routing.py", line 266, in handle
    await self.app(scope, receive, send)
  File "H:\Documents\GitHub\Assignment3\.venv\lib\site-packages\starlette\routing.py", line 65, in app
    response = await func(request)
  File "H:\Documents\GitHub\Assignment3\.venv\lib\site-packages\fastapi\routing.py", line 227, in app
    raw_response = await run_endpoint_function(
  File "H:\Documents\GitHub\Assignment3\.venv\lib\site-packages\fastapi\routing.py", line 160, in run_endpoint_function
    return await dependant.call(**values)
  File "H:\Documents\GitHub\Assignment3\src\.\main.py", line 305, in qualityinspection
    response = test_model.qualityinspection(file)
  File "H:\Documents\GitHub\Assignment3\src\api_functions\test_model.py", line 14, in qualityinspection
    model = joblib.load('./model.pkl')
  File "H:\Documents\GitHub\Assignment3\.venv\lib\site-packages\joblib\numpy_pickle.py", line 587, in load
    obj = _unpickle(fobj, filename, mmap_mode)
  File "H:\Documents\GitHub\Assignment3\.venv\lib\site-packages\joblib\numpy_pickle.py", line 506, in _unpickle
    obj = unpickler.load()
  File "C:\Program Files\WindowsApps\PythonSoftwareFoundation.Python.3.10_3.10.1520.0_x64__qbz5n2kfra8p0\lib\pickle.py", line 1213, in load
    dispatch[key[0]](self)
  File "C:\Program Files\WindowsApps\PythonSoftwareFoundation.Python.3.10_3.10.1520.0_x64__qbz5n2kfra8p0\lib\pickle.py", line 1590, in load_reduce
    stack[-1] = func(*args)
  File "H:\Documents\GitHub\Assignment3\.venv\lib\site-packages\keras\saving\pickle_utils.py", line 48, in deserialize_model_from_bytecode
    model = save_module.load_model(temp_dir)
  File "H:\Documents\GitHub\Assignment3\.venv\lib\site-packages\keras\utils\traceback_utils.py", line 67, in error_handler
    raise e.with_traceback(filtered_tb) from None
  File "H:\Documents\GitHub\Assignment3\.venv\lib\site-packages\tensorflow\python\saved_model\load.py", line 915, in load_partial
    raise FileNotFoundError(
FileNotFoundError: Unsuccessful TensorSliceReader constructor: Failed to find any matching files for ram://c54c37df-11b2-49c9-abbc-8652341999be/variables/variables
 You may be trying to load on a different device from the computational device. Consider setting the `experimental_io_device` option in `tf.saved_model.LoadOptions` to the io_device such as '/job:localhost'.
2022-07-15 02:08:04,879 loglevel=INFO   Shutting down
2022-07-15 18:39:20,756 loglevel=INFO   Started server process [5656]
2022-07-15 18:39:20,757 loglevel=INFO   Waiting for application startup.
2022-07-15 18:39:20,757 loglevel=INFO   Application startup complete.
2022-07-15 18:39:21,673 loglevel=INFO   rid=WO8F1Z request url=http://127.0.0.1:8000/ completed_in=1.00ms status_code=200
2022-07-15 18:39:21,794 loglevel=INFO   rid=9TVJQZ request url=http://127.0.0.1:8000/static/0041e69431bf872309d1aff628b6494f.jpg completed_in=47.04ms status_code=200
2022-07-15 18:39:23,064 loglevel=INFO   rid=S1IGTA request url=http://127.0.0.1:8000/docs completed_in=0.00ms status_code=200
2022-07-15 18:39:23,280 loglevel=INFO   rid=6U0DJE request url=http://127.0.0.1:8000/openapi.json completed_in=5.00ms status_code=200
2022-07-15 18:39:37,098 loglevel=ERROR  Exception in ASGI application
Traceback (most recent call last):
  File "H:\Documents\GitHub\Assignment3\.venv\lib\site-packages\uvicorn\protocols\http\httptools_impl.py", line 372, in run_asgi
    result = await app(self.scope, self.receive, self.send)
  File "H:\Documents\GitHub\Assignment3\.venv\lib\site-packages\uvicorn\middleware\proxy_headers.py", line 75, in __call__
    return await self.app(scope, receive, send)
  File "H:\Documents\GitHub\Assignment3\.venv\lib\site-packages\fastapi\applications.py", line 269, in __call__
    await super().__call__(scope, receive, send)
  File "H:\Documents\GitHub\Assignment3\.venv\lib\site-packages\starlette\applications.py", line 124, in __call__
    await self.middleware_stack(scope, receive, send)
  File "H:\Documents\GitHub\Assignment3\.venv\lib\site-packages\starlette\middleware\errors.py", line 184, in __call__
    raise exc
  File "H:\Documents\GitHub\Assignment3\.venv\lib\site-packages\starlette\middleware\errors.py", line 162, in __call__
    await self.app(scope, receive, _send)
  File "H:\Documents\GitHub\Assignment3\.venv\lib\site-packages\starlette\middleware\base.py", line 68, in __call__
    response = await self.dispatch_func(request, call_next)
  File "H:\Documents\GitHub\Assignment3\src\.\main.py", line 245, in log_requests
    response = await call_next(request)
  File "H:\Documents\GitHub\Assignment3\.venv\lib\site-packages\starlette\middleware\base.py", line 46, in call_next
    raise app_exc
  File "H:\Documents\GitHub\Assignment3\.venv\lib\site-packages\starlette\middleware\base.py", line 36, in coro
    await self.app(scope, request.receive, send_stream.send)
  File "H:\Documents\GitHub\Assignment3\.venv\lib\site-packages\starlette\exceptions.py", line 93, in __call__
    raise exc
  File "H:\Documents\GitHub\Assignment3\.venv\lib\site-packages\starlette\exceptions.py", line 82, in __call__
    await self.app(scope, receive, sender)
  File "H:\Documents\GitHub\Assignment3\.venv\lib\site-packages\fastapi\middleware\asyncexitstack.py", line 21, in __call__
    raise e
  File "H:\Documents\GitHub\Assignment3\.venv\lib\site-packages\fastapi\middleware\asyncexitstack.py", line 18, in __call__
    await self.app(scope, receive, send)
  File "H:\Documents\GitHub\Assignment3\.venv\lib\site-packages\starlette\routing.py", line 670, in __call__
    await route.handle(scope, receive, send)
  File "H:\Documents\GitHub\Assignment3\.venv\lib\site-packages\starlette\routing.py", line 266, in handle
    await self.app(scope, receive, send)
  File "H:\Documents\GitHub\Assignment3\.venv\lib\site-packages\starlette\routing.py", line 65, in app
    response = await func(request)
  File "H:\Documents\GitHub\Assignment3\.venv\lib\site-packages\fastapi\routing.py", line 227, in app
    raw_response = await run_endpoint_function(
  File "H:\Documents\GitHub\Assignment3\.venv\lib\site-packages\fastapi\routing.py", line 160, in run_endpoint_function
    return await dependant.call(**values)
  File "H:\Documents\GitHub\Assignment3\src\.\main.py", line 305, in qualityinspection
    response = test_model.qualityinspection(file)
  File "H:\Documents\GitHub\Assignment3\src\api_functions\test_model.py", line 14, in qualityinspection
    model = joblib.load('./model.pkl')
  File "H:\Documents\GitHub\Assignment3\.venv\lib\site-packages\joblib\numpy_pickle.py", line 587, in load
    obj = _unpickle(fobj, filename, mmap_mode)
  File "H:\Documents\GitHub\Assignment3\.venv\lib\site-packages\joblib\numpy_pickle.py", line 506, in _unpickle
    obj = unpickler.load()
  File "C:\Program Files\WindowsApps\PythonSoftwareFoundation.Python.3.10_3.10.1520.0_x64__qbz5n2kfra8p0\lib\pickle.py", line 1213, in load
    dispatch[key[0]](self)
  File "C:\Program Files\WindowsApps\PythonSoftwareFoundation.Python.3.10_3.10.1520.0_x64__qbz5n2kfra8p0\lib\pickle.py", line 1590, in load_reduce
    stack[-1] = func(*args)
  File "H:\Documents\GitHub\Assignment3\.venv\lib\site-packages\keras\saving\pickle_utils.py", line 48, in deserialize_model_from_bytecode
    model = save_module.load_model(temp_dir)
  File "H:\Documents\GitHub\Assignment3\.venv\lib\site-packages\keras\utils\traceback_utils.py", line 67, in error_handler
    raise e.with_traceback(filtered_tb) from None
  File "H:\Documents\GitHub\Assignment3\.venv\lib\site-packages\tensorflow\python\saved_model\load.py", line 915, in load_partial
    raise FileNotFoundError(
FileNotFoundError: Unsuccessful TensorSliceReader constructor: Failed to find any matching files for ram://b94a217c-31be-4cca-9e84-b80d58fe696a/variables/variables
 You may be trying to load on a different device from the computational device. Consider setting the `experimental_io_device` option in `tf.saved_model.LoadOptions` to the io_device such as '/job:localhost'.
2022-07-15 18:41:59,774 loglevel=INFO   Started server process [16148]
2022-07-15 18:41:59,774 loglevel=INFO   Waiting for application startup.
2022-07-15 18:41:59,775 loglevel=INFO   Application startup complete.
2022-07-15 18:42:01,933 loglevel=INFO   rid=IQOPFQ request url=http://127.0.0.1:8000/docs completed_in=0.00ms status_code=200
2022-07-15 18:42:02,062 loglevel=INFO   rid=UDI1YC request url=http://127.0.0.1:8000/openapi.json completed_in=3.00ms status_code=200
2022-07-15 18:42:06,895 loglevel=ERROR  Exception in ASGI application
Traceback (most recent call last):
  File "H:\Documents\GitHub\Assignment3\.venv\lib\site-packages\uvicorn\protocols\http\httptools_impl.py", line 372, in run_asgi
    result = await app(self.scope, self.receive, self.send)
  File "H:\Documents\GitHub\Assignment3\.venv\lib\site-packages\uvicorn\middleware\proxy_headers.py", line 75, in __call__
    return await self.app(scope, receive, send)
  File "H:\Documents\GitHub\Assignment3\.venv\lib\site-packages\fastapi\applications.py", line 269, in __call__
    await super().__call__(scope, receive, send)
  File "H:\Documents\GitHub\Assignment3\.venv\lib\site-packages\starlette\applications.py", line 124, in __call__
    await self.middleware_stack(scope, receive, send)
  File "H:\Documents\GitHub\Assignment3\.venv\lib\site-packages\starlette\middleware\errors.py", line 184, in __call__
    raise exc
  File "H:\Documents\GitHub\Assignment3\.venv\lib\site-packages\starlette\middleware\errors.py", line 162, in __call__
    await self.app(scope, receive, _send)
  File "H:\Documents\GitHub\Assignment3\.venv\lib\site-packages\starlette\middleware\base.py", line 68, in __call__
    response = await self.dispatch_func(request, call_next)
  File "H:\Documents\GitHub\Assignment3\src\.\main.py", line 245, in log_requests
    response = await call_next(request)
  File "H:\Documents\GitHub\Assignment3\.venv\lib\site-packages\starlette\middleware\base.py", line 46, in call_next
    raise app_exc
  File "H:\Documents\GitHub\Assignment3\.venv\lib\site-packages\starlette\middleware\base.py", line 36, in coro
    await self.app(scope, request.receive, send_stream.send)
  File "H:\Documents\GitHub\Assignment3\.venv\lib\site-packages\starlette\exceptions.py", line 93, in __call__
    raise exc
  File "H:\Documents\GitHub\Assignment3\.venv\lib\site-packages\starlette\exceptions.py", line 82, in __call__
    await self.app(scope, receive, sender)
  File "H:\Documents\GitHub\Assignment3\.venv\lib\site-packages\fastapi\middleware\asyncexitstack.py", line 21, in __call__
    raise e
  File "H:\Documents\GitHub\Assignment3\.venv\lib\site-packages\fastapi\middleware\asyncexitstack.py", line 18, in __call__
    await self.app(scope, receive, send)
  File "H:\Documents\GitHub\Assignment3\.venv\lib\site-packages\starlette\routing.py", line 670, in __call__
    await route.handle(scope, receive, send)
  File "H:\Documents\GitHub\Assignment3\.venv\lib\site-packages\starlette\routing.py", line 266, in handle
    await self.app(scope, receive, send)
  File "H:\Documents\GitHub\Assignment3\.venv\lib\site-packages\starlette\routing.py", line 65, in app
    response = await func(request)
  File "H:\Documents\GitHub\Assignment3\.venv\lib\site-packages\fastapi\routing.py", line 227, in app
    raw_response = await run_endpoint_function(
  File "H:\Documents\GitHub\Assignment3\.venv\lib\site-packages\fastapi\routing.py", line 160, in run_endpoint_function
    return await dependant.call(**values)
  File "H:\Documents\GitHub\Assignment3\src\.\main.py", line 305, in qualityinspection
    response = test_model.qualityinspection(file)
  File "H:\Documents\GitHub\Assignment3\src\api_functions\test_model.py", line 21, in qualityinspection
    model = load_model('model.h5')
  File "H:\Documents\GitHub\Assignment3\.venv\lib\site-packages\keras\utils\traceback_utils.py", line 67, in error_handler
    raise e.with_traceback(filtered_tb) from None
  File "H:\Documents\GitHub\Assignment3\.venv\lib\site-packages\keras\saving\save.py", line 206, in load_model
    raise IOError(f'No file or directory found at {filepath_str}')
OSError: No file or directory found at model.h5
2022-07-15 18:42:43,881 loglevel=INFO   Started server process [8616]
2022-07-15 18:42:43,882 loglevel=INFO   Waiting for application startup.
2022-07-15 18:42:43,882 loglevel=INFO   Application startup complete.
2022-07-15 18:42:46,091 loglevel=INFO   rid=7LQ1EU request url=http://127.0.0.1:8000/docs completed_in=1.00ms status_code=200
2022-07-15 18:42:46,163 loglevel=INFO   rid=W1RXY6 request url=http://127.0.0.1:8000/openapi.json completed_in=4.00ms status_code=200
2022-07-15 18:42:50,283 loglevel=ERROR  Exception in ASGI application
Traceback (most recent call last):
  File "H:\Documents\GitHub\Assignment3\.venv\lib\site-packages\uvicorn\protocols\http\httptools_impl.py", line 372, in run_asgi
    result = await app(self.scope, self.receive, self.send)
  File "H:\Documents\GitHub\Assignment3\.venv\lib\site-packages\uvicorn\middleware\proxy_headers.py", line 75, in __call__
    return await self.app(scope, receive, send)
  File "H:\Documents\GitHub\Assignment3\.venv\lib\site-packages\fastapi\applications.py", line 269, in __call__
    await super().__call__(scope, receive, send)
  File "H:\Documents\GitHub\Assignment3\.venv\lib\site-packages\starlette\applications.py", line 124, in __call__
    await self.middleware_stack(scope, receive, send)
  File "H:\Documents\GitHub\Assignment3\.venv\lib\site-packages\starlette\middleware\errors.py", line 184, in __call__
    raise exc
  File "H:\Documents\GitHub\Assignment3\.venv\lib\site-packages\starlette\middleware\errors.py", line 162, in __call__
    await self.app(scope, receive, _send)
  File "H:\Documents\GitHub\Assignment3\.venv\lib\site-packages\starlette\middleware\base.py", line 68, in __call__
    response = await self.dispatch_func(request, call_next)
  File "H:\Documents\GitHub\Assignment3\src\.\main.py", line 245, in log_requests
    response = await call_next(request)
  File "H:\Documents\GitHub\Assignment3\.venv\lib\site-packages\starlette\middleware\base.py", line 46, in call_next
    raise app_exc
  File "H:\Documents\GitHub\Assignment3\.venv\lib\site-packages\starlette\middleware\base.py", line 36, in coro
    await self.app(scope, request.receive, send_stream.send)
  File "H:\Documents\GitHub\Assignment3\.venv\lib\site-packages\starlette\exceptions.py", line 93, in __call__
    raise exc
  File "H:\Documents\GitHub\Assignment3\.venv\lib\site-packages\starlette\exceptions.py", line 82, in __call__
    await self.app(scope, receive, sender)
  File "H:\Documents\GitHub\Assignment3\.venv\lib\site-packages\fastapi\middleware\asyncexitstack.py", line 21, in __call__
    raise e
  File "H:\Documents\GitHub\Assignment3\.venv\lib\site-packages\fastapi\middleware\asyncexitstack.py", line 18, in __call__
    await self.app(scope, receive, send)
  File "H:\Documents\GitHub\Assignment3\.venv\lib\site-packages\starlette\routing.py", line 670, in __call__
    await route.handle(scope, receive, send)
  File "H:\Documents\GitHub\Assignment3\.venv\lib\site-packages\starlette\routing.py", line 266, in handle
    await self.app(scope, receive, send)
  File "H:\Documents\GitHub\Assignment3\.venv\lib\site-packages\starlette\routing.py", line 65, in app
    response = await func(request)
  File "H:\Documents\GitHub\Assignment3\.venv\lib\site-packages\fastapi\routing.py", line 227, in app
    raw_response = await run_endpoint_function(
  File "H:\Documents\GitHub\Assignment3\.venv\lib\site-packages\fastapi\routing.py", line 160, in run_endpoint_function
    return await dependant.call(**values)
  File "H:\Documents\GitHub\Assignment3\src\.\main.py", line 305, in qualityinspection
    response = test_model.qualityinspection(file)
  File "H:\Documents\GitHub\Assignment3\src\api_functions\test_model.py", line 21, in qualityinspection
    model = load_model(model_path)
  File "H:\Documents\GitHub\Assignment3\.venv\lib\site-packages\keras\utils\traceback_utils.py", line 67, in error_handler
    raise e.with_traceback(filtered_tb) from None
  File "H:\Documents\GitHub\Assignment3\.venv\lib\site-packages\keras\saving\save.py", line 206, in load_model
    raise IOError(f'No file or directory found at {filepath_str}')
OSError: No file or directory found at H:\Documents\GitHub\Assignment3\model,h5
2022-07-15 18:43:03,466 loglevel=INFO   Started server process [1964]
2022-07-15 18:43:03,467 loglevel=INFO   Waiting for application startup.
2022-07-15 18:43:03,467 loglevel=INFO   Application startup complete.
2022-07-15 18:43:04,021 loglevel=ERROR  Exception in ASGI application
Traceback (most recent call last):
  File "H:\Documents\GitHub\Assignment3\.venv\lib\site-packages\uvicorn\protocols\http\httptools_impl.py", line 372, in run_asgi
    result = await app(self.scope, self.receive, self.send)
  File "H:\Documents\GitHub\Assignment3\.venv\lib\site-packages\uvicorn\middleware\proxy_headers.py", line 75, in __call__
    return await self.app(scope, receive, send)
  File "H:\Documents\GitHub\Assignment3\.venv\lib\site-packages\fastapi\applications.py", line 269, in __call__
    await super().__call__(scope, receive, send)
  File "H:\Documents\GitHub\Assignment3\.venv\lib\site-packages\starlette\applications.py", line 124, in __call__
    await self.middleware_stack(scope, receive, send)
  File "H:\Documents\GitHub\Assignment3\.venv\lib\site-packages\starlette\middleware\errors.py", line 184, in __call__
    raise exc
  File "H:\Documents\GitHub\Assignment3\.venv\lib\site-packages\starlette\middleware\errors.py", line 162, in __call__
    await self.app(scope, receive, _send)
  File "H:\Documents\GitHub\Assignment3\.venv\lib\site-packages\starlette\middleware\base.py", line 68, in __call__
    response = await self.dispatch_func(request, call_next)
  File "H:\Documents\GitHub\Assignment3\src\.\main.py", line 245, in log_requests
    response = await call_next(request)
  File "H:\Documents\GitHub\Assignment3\.venv\lib\site-packages\starlette\middleware\base.py", line 46, in call_next
    raise app_exc
  File "H:\Documents\GitHub\Assignment3\.venv\lib\site-packages\starlette\middleware\base.py", line 36, in coro
    await self.app(scope, request.receive, send_stream.send)
  File "H:\Documents\GitHub\Assignment3\.venv\lib\site-packages\starlette\exceptions.py", line 93, in __call__
    raise exc
  File "H:\Documents\GitHub\Assignment3\.venv\lib\site-packages\starlette\exceptions.py", line 82, in __call__
    await self.app(scope, receive, sender)
  File "H:\Documents\GitHub\Assignment3\.venv\lib\site-packages\fastapi\middleware\asyncexitstack.py", line 21, in __call__
    raise e
  File "H:\Documents\GitHub\Assignment3\.venv\lib\site-packages\fastapi\middleware\asyncexitstack.py", line 18, in __call__
    await self.app(scope, receive, send)
  File "H:\Documents\GitHub\Assignment3\.venv\lib\site-packages\starlette\routing.py", line 670, in __call__
    await route.handle(scope, receive, send)
  File "H:\Documents\GitHub\Assignment3\.venv\lib\site-packages\starlette\routing.py", line 266, in handle
    await self.app(scope, receive, send)
  File "H:\Documents\GitHub\Assignment3\.venv\lib\site-packages\starlette\routing.py", line 65, in app
    response = await func(request)
  File "H:\Documents\GitHub\Assignment3\.venv\lib\site-packages\fastapi\routing.py", line 227, in app
    raw_response = await run_endpoint_function(
  File "H:\Documents\GitHub\Assignment3\.venv\lib\site-packages\fastapi\routing.py", line 160, in run_endpoint_function
    return await dependant.call(**values)
  File "H:\Documents\GitHub\Assignment3\src\.\main.py", line 305, in qualityinspection
    response = test_model.qualityinspection(file)
  File "H:\Documents\GitHub\Assignment3\src\api_functions\test_model.py", line 21, in qualityinspection
    model = load_model(model_path)
  File "H:\Documents\GitHub\Assignment3\.venv\lib\site-packages\keras\utils\traceback_utils.py", line 67, in error_handler
    raise e.with_traceback(filtered_tb) from None
  File "H:\Documents\GitHub\Assignment3\.venv\lib\site-packages\keras\saving\save.py", line 206, in load_model
    raise IOError(f'No file or directory found at {filepath_str}')
OSError: No file or directory found at H:\Documents\GitHub\Assignment3\model.h5
2022-07-15 18:43:05,601 loglevel=INFO   rid=1HZ03J request url=http://127.0.0.1:8000/docs completed_in=0.00ms status_code=200
2022-07-15 18:43:05,668 loglevel=INFO   rid=2PVGI5 request url=http://127.0.0.1:8000/openapi.json completed_in=4.00ms status_code=200
2022-07-15 18:43:09,988 loglevel=ERROR  Exception in ASGI application
Traceback (most recent call last):
  File "H:\Documents\GitHub\Assignment3\.venv\lib\site-packages\uvicorn\protocols\http\httptools_impl.py", line 372, in run_asgi
    result = await app(self.scope, self.receive, self.send)
  File "H:\Documents\GitHub\Assignment3\.venv\lib\site-packages\uvicorn\middleware\proxy_headers.py", line 75, in __call__
    return await self.app(scope, receive, send)
  File "H:\Documents\GitHub\Assignment3\.venv\lib\site-packages\fastapi\applications.py", line 269, in __call__
    await super().__call__(scope, receive, send)
  File "H:\Documents\GitHub\Assignment3\.venv\lib\site-packages\starlette\applications.py", line 124, in __call__
    await self.middleware_stack(scope, receive, send)
  File "H:\Documents\GitHub\Assignment3\.venv\lib\site-packages\starlette\middleware\errors.py", line 184, in __call__
    raise exc
  File "H:\Documents\GitHub\Assignment3\.venv\lib\site-packages\starlette\middleware\errors.py", line 162, in __call__
    await self.app(scope, receive, _send)
  File "H:\Documents\GitHub\Assignment3\.venv\lib\site-packages\starlette\middleware\base.py", line 68, in __call__
    response = await self.dispatch_func(request, call_next)
  File "H:\Documents\GitHub\Assignment3\src\.\main.py", line 245, in log_requests
    response = await call_next(request)
  File "H:\Documents\GitHub\Assignment3\.venv\lib\site-packages\starlette\middleware\base.py", line 46, in call_next
    raise app_exc
  File "H:\Documents\GitHub\Assignment3\.venv\lib\site-packages\starlette\middleware\base.py", line 36, in coro
    await self.app(scope, request.receive, send_stream.send)
  File "H:\Documents\GitHub\Assignment3\.venv\lib\site-packages\starlette\exceptions.py", line 93, in __call__
    raise exc
  File "H:\Documents\GitHub\Assignment3\.venv\lib\site-packages\starlette\exceptions.py", line 82, in __call__
    await self.app(scope, receive, sender)
  File "H:\Documents\GitHub\Assignment3\.venv\lib\site-packages\fastapi\middleware\asyncexitstack.py", line 21, in __call__
    raise e
  File "H:\Documents\GitHub\Assignment3\.venv\lib\site-packages\fastapi\middleware\asyncexitstack.py", line 18, in __call__
    await self.app(scope, receive, send)
  File "H:\Documents\GitHub\Assignment3\.venv\lib\site-packages\starlette\routing.py", line 670, in __call__
    await route.handle(scope, receive, send)
  File "H:\Documents\GitHub\Assignment3\.venv\lib\site-packages\starlette\routing.py", line 266, in handle
    await self.app(scope, receive, send)
  File "H:\Documents\GitHub\Assignment3\.venv\lib\site-packages\starlette\routing.py", line 65, in app
    response = await func(request)
  File "H:\Documents\GitHub\Assignment3\.venv\lib\site-packages\fastapi\routing.py", line 227, in app
    raw_response = await run_endpoint_function(
  File "H:\Documents\GitHub\Assignment3\.venv\lib\site-packages\fastapi\routing.py", line 160, in run_endpoint_function
    return await dependant.call(**values)
  File "H:\Documents\GitHub\Assignment3\src\.\main.py", line 305, in qualityinspection
    response = test_model.qualityinspection(file)
  File "H:\Documents\GitHub\Assignment3\src\api_functions\test_model.py", line 21, in qualityinspection
    model = load_model(model_path)
  File "H:\Documents\GitHub\Assignment3\.venv\lib\site-packages\keras\utils\traceback_utils.py", line 67, in error_handler
    raise e.with_traceback(filtered_tb) from None
  File "H:\Documents\GitHub\Assignment3\.venv\lib\site-packages\keras\saving\save.py", line 206, in load_model
    raise IOError(f'No file or directory found at {filepath_str}')
OSError: No file or directory found at H:\Documents\GitHub\Assignment3\model.h5
2022-07-15 18:43:34,495 loglevel=INFO   Started server process [14364]
2022-07-15 18:43:34,496 loglevel=INFO   Waiting for application startup.
2022-07-15 18:43:34,496 loglevel=INFO   Application startup complete.
2022-07-15 18:43:34,500 loglevel=INFO   rid=9PCMGY request url=http://127.0.0.1:8000/docs completed_in=0.00ms status_code=200
2022-07-15 18:43:34,578 loglevel=INFO   rid=788RXX request url=http://127.0.0.1:8000/openapi.json completed_in=4.00ms status_code=200
2022-07-15 18:43:43,951 loglevel=INFO   rid=W12LO9 request url=http://127.0.0.1:8000/qualityinspection/ completed_in=5739.41ms status_code=200
2022-07-15 18:43:48,910 loglevel=INFO   Shutting down
